Workbook

Sheet industry_fields
A1: company_cd | B1: field_code | C1: field_name | D1: org_desc | E1: facility_desc | F1: sort_order | G1: is_use | H1: created_at | I1: updated_at | J1: created_by | K1: updated_by
A2: TESTCOMP | B2: AICC | C2: AICC | D2: 콜센터 연계 | E2: 금융, 공공, 교통, 일반 Enterp. 등 | F2: 11 | G2: Y | H2: 46056.917 | I2: 46060.35
A3: TESTCOMP | B3: 공공 | C3: 공공 | D3: 중앙·지방 행정기관 | E3: 관공서, 주민센터, 복지관, 체육 시설, 행정센터 | F3: 2 | G3: Y | H3: 46056.917 | I3: 46060.35
A4: TESTCOMP | B4: 교육 | C4: 교육 | D4: 초중등·고등·기타교육 | E4: 도서관, 학교, 학원, 직업훈련기관 | F4: 3 | G4: Y | H4: 46056.917 | I4: 46060.35
A5: TESTCOMP | B5: 교통 | C5: 교통 | D5: 육상·철도·항공·해운 | E5: 버스, 지하철, 공항, 물류센터, 주유소 | F5: 5 | G5: Y | H5: 46056.917 | I5: 46060.35
A6: TESTCOMP | B6: 금융 | C6: 금융 | D6: 은행·보험·증권 | E6: 지점·콜센터·모바일 | F6: 4 | G6: Y | H6: 46056.917 | I6: 46060.35
A7: TESTCOMP | B7: 문화 | C7: 문화 | D7: 공연·전시·스포츠, 오락,서비스 | E7: 극장, 박물관, 테마파크 | F7: 6 | G7: Y | H7: 46056.917 | I7: 46060.35
A8: TESTCOMP | B8: 방송 | C8: 방송 | D8: 방송업 | E8: 지상파·케이블·OTT | F8: 9 | G8: Y | H8: 46056.917 | I8: 46060.35
A9: TESTCOMP | B9: 법률 | C9: 법률 | D9: 법무관련 서비스 | E9: 변호사사무소, 법무법인 | F9: 10 | G9: Y | H9: 46056.917 | I9: 46060.35
A10: TESTCOMP | B10: 숙박 | C10: 숙박 | D10: 호텔·리조트.숙박 | E10: 호텔, 리조트, 콘도 | F10: 7 | G10: Y | H10: 46056.917 | I10: 46060.35
A11: TESTCOMP | B11: 의료 | C11: 의료 | D11: 병원·의원·복지시설 | E11: 종합병원, 지방 의료원, 보건소, 요양병원 | F11: 1 | G11: Y | H11: 46056.917 | I11: 46060.35
A12: TESTCOMP | B12: 제조 | C12: 제조 | D12: 제조 | E12: 전기, 전자, 기계 | F12: 8 | G12: Y | H12: 46056.917 | I12: 46060.35

Sheet service_codes
A1: company_cd | B1: service_code | C1: parent_code | D1: service_name | E1: display_name | F1: sort_order | G1: is_use | H1: created_at | I1: updated_at | J1: created_by | K1: updated_by
A2: TESTCOMP | B2: AI서비스 | D2: AI서비스 | E2: AI서비스 | F2: 1 | G2: Y | H2: 46056.917 | I2: 46060.351
A3: TESTCOMP | B3: AI서비스-IPCC | C3: AI서비스 | D3: IPCC | E3: AI서비스-IPCC | F3: 2 | G3: Y | H3: 46056.917 | I3: 46060.351
A4: TESTCOMP | B4: AI서비스-SI부문 | C4: AI서비스 | D4: SI부문 | E4: AI서비스-SI부문 | F4: 1 | G4: Y | H4: 46056.917 | I4: 46060.351
A5: TESTCOMP | B5: AI서비스-시스템 | C5: AI서비스 | D5: 시스템 | E5: AI서비스-시스템 | F5: 3 | G5: Y | H5: 46056.917 | I5: 46060.351
A6: TESTCOMP | B6: AI서비스-패키지 | C6: AI서비스 | D6: 패키지 | E6: AI서비스-패키지 | F6: 4 | G6: Y | H6: 46056.917 | I6: 46060.351
A7: TESTCOMP | B7: AI수어 | D7: AI수어 | E7: AI수어 | F7: 2 | G7: Y | H7: 46056.917 | I7: 46060.351
A8: TESTCOMP | B8: AI수어-과제형 | C8: AI수어 | D8: 과제형 | E8: AI수어-과제형 | F8: 7 | G8: Y | H8: 46056.917 | I8: 46060.351
A9: TESTCOMP | B9: AI수어-구독형 | C9: AI수어 | D9: 구독형 | E9: AI수어-구독형 | F9: 6 | G9: Y | H9: 46056.917 | I9: 46060.351
A10: TESTCOMP | B10: AI수어-구축형 | C10: AI수어 | D10: 구축형 | E10: AI수어-구축형 | F10: 5 | G10: Y | H10: 46056.917 | I10: 46060.351
A11: TESTCOMP | B11: AI수어-대외매출 | C11: AI수어 | D11: 대외매출 | E11: AI수어-대외매출 | F11: 8 | G11: Y | H11: 46056.917 | I11: 46060.351
A12: TESTCOMP | B12: 기타 | D12: 기타 | E12: 기타 | F12: 3 | G12: Y | H12: 46056.917 | I12: 46060.351
A13: TESTCOMP | B13: 기타-유지보수(MA) | C13: 기타 | D13: 유지보수(MA) | E13: 기타-유지보수(MA) | F13: 10 | G13: Y | H13: 46056.917 | I13: 46060.351
A14: TESTCOMP | B14: 기타-유지보수(SM) | C14: 기타 | D14: 유지보수(SM) | E14: 기타-유지보수(SM) | F14: 9 | G14: Y | H14: 46056.917 | I14: 46060.351

Sheet org_units
A1: company_cd | B1: org_id | C1: org_name | D1: parent_id | E1: org_type | F1: sort_order | G1: is_use | H1: created_at | I1: updated_at | J1: created_by | K1: updated_by
A2: TESTCOMP | B2: 1 | C2: AX기술영업팀 | E2: TEAM | F2: 0 | G2: Y | H2: 46056.917 | I2: 46060.351
A3: TESTCOMP | B3: 2 | C3: AX프로젝트팀 | E3: TEAM | F3: 0 | G3: Y | H3: 46056.917 | I3: 46060.351
A4: TESTCOMP | B4: 3 | C4: AX기술수행팀 | E4: TEAM | F4: 0 | G4: Y | H4: 46056.917 | I4: 46060.351

Sheet comm_code
A1: company_cd | B1: group_code | C1: group_name | D1: code | E1: code_name | F1: sort_order | G1: is_use | H1: created_at | I1: updated_at | J1: created_by | K1: updated_by
A2: TESTCOMP | B2: ACTIVITY_TYPE | C2: 활동유형 | D2: CONTRACT | E2: 계약 | F2: 3 | G2: Y | H2: 46061.749 | I2: 46061.749 | J2: system | K2: system
A3: TESTCOMP | B3: ACTIVITY_TYPE | C3: 활동유형 | D3: ETC | E3: 기타 | F3: 6 | G3: Y | H3: 46061.749 | I3: 46061.749 | J3: system | K3: system
A4: TESTCOMP | B4: ACTIVITY_TYPE | C4: 활동유형 | D4: FOLLOWUP | E4: 후속 | F4: 4 | G4: Y | H4: 46061.749 | I4: 46061.749 | J4: system | K4: system
A5: TESTCOMP | B5: ACTIVITY_TYPE | C5: 활동유형 | D5: MEETING | E5: 미팅 | F5: 1 | G5: Y | H5: 46061.749 | I5: 46061.749 | J5: system | K5: system
A6: TESTCOMP | B6: ACTIVITY_TYPE | C6: 활동유형 | D6: PROPOSAL | E6: 제안 | F6: 2 | G6: Y | H6: 46061.749 | I6: 46061.749 | J6: system | K6: system
A7: TESTCOMP | B7: ACTIVITY_TYPE | C7: 활동유형 | D7: SUPPORT | E7: 지원 | F7: 5 | G7: Y | H7: 46061.749 | I7: 46061.749 | J7: system | K7: system
A8: TESTCOMP | B8: GROUP_CODE | C8: 그룹코드 | D8: NOTICE_CATEGORY | E8: 게시판구분 | F8: 2 | G8: Y | H8: 46056.642 | I8: 46060.351
A9: TESTCOMP | B9: GROUP_CODE | C9: 그룹코드 | D9: PROJECT_ATTRIBUTE | E9: 사업속성 | F9: 3 | G9: Y | H9: 46056.642 | I9: 46060.351
A10: TESTCOMP | B10: GROUP_CODE | C10: 그룹코드 | D10: ROLE | E10: 역할 | F10: 4 | G10: Y | H10: 46056.642 | I10: 46060.351
A11: TESTCOMP | B11: GROUP_CODE | C11: 그룹코드 | D11: STAGE | E11: 진행단계 | F11: 5 | G11: Y | H11: 46056.642 | I11: 46060.351
A12: TESTCOMP | B12: NOTICE_CATEGORY | C12: 게시판구분 | D12: DEV | E12: DEV | F12: 4 | G12: Y | H12: 46039.934 | I12: 46060.351 | J12: admin
A13: TESTCOMP | B13: NOTICE_CATEGORY | C13: 게시판구분 | D13: GENERAL | E13: GENERAL | F13: 2 | G13: Y | H13: 46039.934 | I13: 46060.351 | J13: admin
A14: TESTCOMP | B14: NOTICE_CATEGORY | C14: 게시판구분 | D14: HR | E14: HR | F14: 6 | G14: Y | H14: 46039.934 | I14: 46060.351 | J14: admin
A15: TESTCOMP | B15: NOTICE_CATEGORY | C15: 게시판구분 | D15: SALES | E15: SALES | F15: 1 | G15: Y | H15: 46039.934 | I15: 46060.351 | J15: admin
A16: TESTCOMP | B16: NOTICE_CATEGORY | C16: 게시판구분 | D16: SYSTEM | E16: SYSTEM | F16: 5 | G16: Y | H16: 46039.934 | I16: 46060.351 | J16: admin
A17: TESTCOMP | B17: NOTICE_CATEGORY | C17: 게시판구분 | D17: WELFARE | E17: WELFARE | F17: 3 | G17: Y | H17: 46039.934 | I17: 46060.351 | J17: admin
A18: TESTCOMP | B18: PROJECT_ATTRIBUTE | C18: 사업속성 | D18: ATTR_BIZ_STR | E18: 사업구도 | F18: 4 | G18: Y | H18: 46030.63 | I18: 46060.351
A19: TESTCOMP | B19: PROJECT_ATTRIBUTE | C19: 사업속성 | D19: ATTR_CHANGE | E19: 변동여부 | F19: 5 | G19: Y | H19: 46030.63 | I19: 46060.351
A20: TESTCOMP | B20: PROJECT_ATTRIBUTE | C20: 사업속성 | D20: ATTR_CON_TIME | E20: 계약시기 | F20: 2 | G20: Y | H20: 46030.63 | I20: 46060.351
A21: TESTCOMP | B21: PROJECT_ATTRIBUTE | C21: 사업속성 | D21: ATTR_CONFIRM | E21: 확정여부 | F21: 6 | G21: Y | H21: 46035.839 | I21: 46060.351 | J21: 양승구
A22: TESTCOMP | B22: PROJECT_ATTRIBUTE | C22: 사업속성 | D22: ATTR_ORD_TIME | E22: 발주시기 | F22: 1 | G22: Y | H22: 46030.63 | I22: 46060.351
A23: TESTCOMP | B23: PROJECT_ATTRIBUTE | C23: 사업속성 | D23: ATTR_SALES | E23: 매출정보 | F23: 3 | G23: Y | H23: 46030.63 | I23: 46060.351
A24: TESTCOMP | B24: ROLE | C24: 역할 | D24: Admin | E24: 어드민 | F24: 1 | G24: Y | H24: 46033.669 | I24: 46060.351
A25: TESTCOMP | B25: ROLE | C25: 역할 | D25: User | E25: 사용자 | F25: 2 | G25: Y | H25: 46033.669 | I25: 46060.351
A26: TESTCOMP | B26: ROLE | C26: 역할 | D26: Viewer | E26: 조회 | F26: 3 | G26: Y | H26: 46033.669 | I26: 46060.351
A27: TESTCOMP | B27: STAGE | C27: 진행단계 | D27: S01 | E27: 1 영업중 | F27: 1 | G27: Y | H27: 46030.63 | I27: 46060.351
A28: TESTCOMP | B28: STAGE | C28: 진행단계 | D28: S02 | E28: 2 견적제출 | F28: 2 | G28: Y | H28: 46030.63 | I28: 46060.351
A29: TESTCOMP | B29: STAGE | C29: 진행단계 | D29: S03 | E29: 3 제안중 | F29: 3 | G29: Y | H29: 46030.63 | I29: 46060.351
A30: TESTCOMP | B30: STAGE | C30: 진행단계 | D30: S04 | E30: 4 입찰중 | F30: 4 | G30: Y | H30: 46030.63 | I30: 46060.351
A31: TESTCOMP | B31: STAGE | C31: 진행단계 | D31: S05 | E31: 5 DROP | F31: 5 | G31: Y | H31: 46030.63 | I31: 46060.351
A32: TESTCOMP | B32: STAGE | C32: 진행단계 | D32: S06 | E32: 6 실주 | F32: 6 | G32: Y | H32: 46030.63 | I32: 46060.351
A33: TESTCOMP | B33: STAGE | C33: 진행단계 | D33: S07 | E33: 7 수주완료 | F33: 7 | G33: Y | H33: 46030.63 | I33: 46060.351
... A35: TESTCOMP | B35: STAGE | C35: 진행단계 | D35: S09 | E35: 9 유지보수 | F35: 9 | G35: Y | H35: 46030.63 | I35: 46060.351

Sheet psms_schema
A1: table_name | B1: column_name | C1: col_pos | D1: is_pk | E1: data_type | F1: data_length | G1: comments
A2: auth_forms | B2: company_cd | C2: 1 | D2: Y | E2: varchar | F2: 20 | G2: 회사 코드
A3: auth_forms | B3: form_id | C3: 2 | D3: Y | E3: varchar | F3: 50 | G3: VBA UserForm 객체 이름
A4: auth_forms | B4: form_name | C4: 3 | D4: N | E4: varchar | F4: 100 | G4: 화면 한글명
A5: auth_forms | B5: created_at | C5: 4 | D5: N | E5: timestamp | G5: 최초 생성일시
A6: auth_forms | B6: updated_at | C6: 5 | D6: N | E6: timestamp | G6: 최종 수정일시
A7: auth_forms | B7: created_by | C7: 6 | D7: N | E7: varchar | F7: 50 | G7: 생성자 ID
A8: auth_forms | B8: updated_by | C8: 7 | D8: N | E8: varchar | F8: 50 | G8: 수정자 ID
A9: auth_role_permissions | B9: company_cd | C9: 1 | D9: Y | E9: varchar | F9: 20 | G9: 회사 코드
A10: auth_role_permissions | B10: role | C10: 2 | D10: Y | E10: varchar | F10: 20 | G10: 역할
A11: auth_role_permissions | B11: form_id | C11: 3 | D11: Y | E11: varchar | F11: 50 | G11: 화면 ID
A12: auth_role_permissions | B12: can_view | C12: 4 | D12: N | E12: char | F12: 1 | G12: 조회 권한
A13: auth_role_permissions | B13: can_create | C13: 5 | D13: N | E13: char | F13: 1 | G13: 등록 권한
A14: auth_role_permissions | B14: can_update | C14: 6 | D14: N | E14: char | F14: 1 | G14: 수정 권한
A15: auth_role_permissions | B15: can_delete | C15: 7 | D15: N | E15: char | F15: 1 | G15: 삭제 권한
A16: auth_role_permissions | B16: created_at | C16: 8 | D16: N | E16: timestamp | G16: 최초 생성일시
A17: auth_role_permissions | B17: updated_at | C17: 9 | D17: N | E17: timestamp | G17: 최종 수정일시
A18: auth_role_permissions | B18: created_by | C18: 10 | D18: N | E18: varchar | F18: 50 | G18: 생성자 ID
A19: auth_role_permissions | B19: updated_by | C19: 11 | D19: N | E19: varchar | F19: 50 | G19: 수정자 ID
A20: auth_user_permissions | B20: company_cd | C20: 1 | D20: Y | E20: varchar | F20: 20 | G20: 회사 코드
A21: auth_user_permissions | B21: login_id | C21: 2 | D21: Y | E21: varchar | F21: 50 | G21: 로그인 ID
A22: auth_user_permissions | B22: form_id | C22: 3 | D22: Y | E22: varchar | F22: 50 | G22: 화면 ID
A23: auth_user_permissions | B23: can_view | C23: 4 | D23: N | E23: char | F23: 1 | G23: 조회 권한
A24: auth_user_permissions | B24: can_create | C24: 5 | D24: N | E24: char | F24: 1 | G24: 등록 권한
A25: auth_user_permissions | B25: can_update | C25: 6 | D25: N | E25: char | F25: 1 | G25: 수정 권한
A26: auth_user_permissions | B26: can_delete | C26: 7 | D26: N | E26: char | F26: 1 | G26: 삭제 권한
A27: auth_user_permissions | B27: created_at | C27: 8 | D27: N | E27: timestamp | G27: 최초 생성일시
A28: auth_user_permissions | B28: updated_at | C28: 9 | D28: N | E28: timestamp | G28: 최종 수정일시
A29: auth_user_permissions | B29: created_by | C29: 10 | D29: N | E29: varchar | F29: 50 | G29: 생성자 ID
A30: auth_user_permissions | B30: updated_by | C30: 11 | D30: N | E30: varchar | F30: 50 | G30: 수정자 ID
A31: board_notice_files | B31: company_cd | C31: 1 | D31: Y | E31: varchar | F31: 20 | G31: 회사 코드
A32: board_notice_files | B32: map_id | C32: 2 | D32: Y | E32: int | F32: 10 | G32: 매핑 ID
A33: board_notice_files | B33: notice_id | C33: 3 | D33: N | E33: int | F33: 10 | G33: 공지 ID
A34: board_notice_files | B34: reply_id | C34: 4 | D34: N | E34: int | F34: 10 | G34: 답글 ID
A35: board_notice_files | B35: file_id | C35: 5 | D35: N | E35: int | F35: 10 | G35: 파일 ID
A36: board_notice_files | B36: created_at | C36: 6 | D36: N | E36: timestamp | G36: 생성 일시
A37: board_notice_files | B37: created_by | C37: 7 | D37: N | E37: varchar | F37: 50 | G37: 생성자 ID
A38: board_notice_reactions | B38: company_cd | C38: 1 | D38: Y | E38: varchar | F38: 20 | G38: 회사 코드
A39: board_notice_reactions | B39: notice_id | C39: 2 | D39: Y | E39: int | F39: 10 | G39: 공지 ID
A40: board_notice_reactions | B40: user_id | C40: 3 | D40: Y | E40: varchar | F40: 50 | G40: 사용자 ID
...

Sheet Mig_규칙
A1: Source Sheet Name | B1: Title행 | C1: Source Sheet Column ( :source_value ) | D1: Mig 대상여부 | E1: Mapping Rule | F1: Target Table | G1: Target Column | I1: projects | J1: company_cd | L1: project_history | M1: company_cd | O1: clients | P1: company_cd
A2: 2026년 주요추진사업 | B2: 3 | C2: 주차 | D2: N | I2: projects | J2: pipeline_id | L2: project_history | M2: history_id | O2: clients | P2: client_id
A3: 2026년 주요추진사업 | B3: 3 | C3: 파이프라인 ID | D3: Y | E3: :source_value | F3: projects | G3: pipeline_id | I3: projects | J3: project_name | L3: project_history | M3: pipeline_id | O3: clients | P3: client_name
A4: 2026년 주요추진사업 | B4: 3 | C4: 분야 | D4: N | E4: NULL | F4: projects | G4: field_code | I4: projects | J4: field_code | L4: project_history | M4: base_date | O4: clients | P4: business_number
A5: 2026년 주요추진사업 | B5: 3 | C5: 고객사 | D5: Y | E5: select c.client_id from clients c where c.client_name = :source_value [Not Fount] insert into clients (clint_name) value (:source_value) insert 후 자동채번된 client_id Set | F5: projects | G5: clients | I5: projects | J5: service_code | L5: project_history | M5: record_date | O5: clients | P5: ceo_name
A6: 2026년 주요추진사업 | B6: 3 | C6: 발주처 | D6: Y | E6: select c.client_id from clients c where c.client_name = :source_value [Not Fount] insert into clients (clint_name) value (:source_value) insert 후 자동채번된 client_id Set | F6: projects | G6: clients | I6: projects | J6: manager_id | L6: project_history | M6: progress_stage | O6: clients | P6: address
A7: 2026년 주요추진사업 | B7: 3 | C7: 사업명 | D7: Y | E7: :source_value | F7: projects | G7: project_name | I7: projects | J7: org_id | L7: project_history | M7: activity_type | O7: clients | P7: phone
A8: 2026년 주요추진사업 | B8: 3 | C8: 담당자 | D8: Y | E8: select u.login_id from users u where u.user_name=:source_value | F8: projects | G8: manager_id | I8: projects | J8: customer_id | L8: project_history | M8: strategy_content | O8: clients | P8: email
A9: 2026년 주요추진사업 | B9: 3 | C9: 진행단계 | D9: Y | E9: select cc.code from comm_code cc where cc.group_code='STAGE' and cc.code_name = :source_value | F9: projects | G9: current_stage | I9: projects | J9: ordering_party_id | L9: project_history | M9: creator_id | O9: clients | P9: fax
A10: 2026년 주요추진사업 | B10: 3 | C10: 업무 기준일 | D10: Y | E10: :source_value | F10: project_history | G10: base_date | I10: projects | J10: current_stage | L10: project_history | M10: created_at | O10: clients | P10: homepage
A11: 2026년 주요추진사업 | B11: 3 | C11: 진행상황 및 영업전략 | D11: Y | E11: :source_value | F11: project_history | G11: strategy_content | I11: projects | J11: quoted_amount | L11: project_history | M11: updated_at | O11: clients | P11: industry_type
A12: 2026년 주요추진사업 | B12: 3 | C12: 견적금액 단위 원. VAT제외 | D12: Y | E12: :source_value | F12: projects | G12: quoted_amount | I12: projects | J12: win_probability | L12: project_history | M12: created_by | O12: clients | P12: employee_count
A13: 2026년 주요추진사업 | B13: 3 | C13: 발주시기(예상) | D13: Y | E13: :source_value | F13: project_attributes | G13: attr_code='ATTR_ORD_TIME' attr_value=:source_value | I13: projects | J13: notes | L13: project_history | M13: updated_by | O13: clients | P13: established_date
A14: 2026년 주요추진사업 | B14: 3 | C14: 계약시기(예상) | D14: Y | E14: :source_value | F14: project_attributes | G14: attr_code='ATTR_CON_TIME' attr_value=:source_value | I14: projects | J14: status | O14: clients | P14: is_active
A15: 2026년 주요추진사업 | B15: 3 | C15: 계약일자 | D15: Y | E15: :source_value | F15: project_contracts | G15: contract_date | O15: clients | P15: remarks
A16: 2026년 주요추진사업 | B16: 3 | C16: 프로젝트기간(시작) | D16: Y | E16: :source_value | F16: project_contracts | G16: start_date | O16: clients | P16: created_at
A17: 2026년 주요추진사업 | B17: 3 | C17: 프로젝트기간(종료) | D17: Y | E17: :source_value | F17: project_contracts | G17: end_date | I17: project_attributes | J17: company_cd | L17: project_contracts | M17: company_cd | O17: clients | P17: updated_at
A18: 2026년 주요추진사업 | B18: 3 | C18: 계약(수주금액) 단위 원. VAT제외 | D18: Y | E18: :source_value | F18: project_contracts | G18: order_amount | I18: project_attributes | J18: pipeline_id | L18: project_contracts | M18: pipeline_id | O18: clients | P18: created_by
A19: 2026년 주요추진사업 | B19: 3 | C19: 계약(계약금액) 단위 원. VAT제외 | D19: Y | E19: :source_value | F19: project_contracts | G19: contract_amount | I19: project_attributes | J19: attr_code | L19: project_contracts | M19: contract_date | O19: clients | P19: updated_by
A20: 2026년 주요추진사업 | B20: 3 | C20: 매출 | D20: N | I20: project_attributes | J20: attr_value | L20: project_contracts | M20: start_date
A21: 2026년 주요추진사업 | B21: 3 | C21: 사업구도 ex) 마도 : OOO | D21: Y | E21: :source_value | F21: project_attributes | G21: attr_code='ATTR_BIZ_STR' attr_value=:source_value | I21: project_attributes | J21: updated_at | L21: project_contracts | M21: end_date
A22: 2026년 주요추진사업 | B22: 3 | C22: 이전 파이프라인 | D22: N | I22: project_attributes | J22: created_at | L22: project_contracts | M22: order_amount
A23: 2026년 주요추진사업 | B23: 3 | C23: 비고 | D23: Y | E23: :source_value | F23: projects | G23: notes | I23: project_attributes | J23: created_by | L23: project_contracts | M23: contract_amount
A24: 2025년 주요추진사업(NEW) | B24: 3 | C24: 파이프라인 ID | D24: Y | E24: :source_value | F24: projects | G24: pipeline_id | I24: project_attributes | J24: updated_by | L24: project_contracts | M24: remarks
A25: 2025년 주요추진사업(NEW) | B25: 3 | C25: 분야 | D25: N | E25: NULL | F25: projects | G25: field_code | L25: project_contracts | M25: updated_at
A26: 2025년 주요추진사업(NEW) | B26: 3 | C26: 고객사 | D26: Y | E26: select c.client_id from clients c where c.client_name = :source_value [Not Fount] insert into clients (clint_name) value (:source_value) insert 후 자동채번된 client_id Set | F26: projects | G26: clients | L26: project_contracts | M26: created_at
A27: 2025년 주요추진사업(NEW) | B27: 3 | C27: 발주처 | D27: Y | E27: select c.client_id from clients c where c.client_name = :source_value [Not Fount] insert into clients (clint_name) value (:source_value) insert 후 자동채번된 client_id Set | F27: projects | G27: clients | I27: org_units | J27: company_cd | L27: project_contracts | M27: created_by
A28: 2025년 주요추진사업(NEW) | B28: 3 | C28: 사업명 | D28: Y | E28: :source_value | F28: projects | G28: project_name | I28: org_units | J28: org_id | L28: project_contracts | M28: updated_by
A29: 2025년 주요추진사업(NEW) | B29: 3 | C29: 담당자 | D29: Y | E29: select u.login_id from users u where u.user_name=:source_value | F29: projects | G29: manager_id | I29: org_units | J29: org_name
A30: 2025년 주요추진사업(NEW) | B30: 3 | C30: 진행단계 | D30: Y | E30: select cc.code from comm_code cc where cc.group_code='STAGE' and cc.code_name = :source_value | F30: projects | G30: current_stage | I30: org_units | J30: parent_id | L30: users | M30: company_cd
A31: 2025년 주요추진사업(NEW) | B31: 3 | C31: 발주시기 | D31: Y | E31: :source_value | F31: project_attributes | G31: attr_code='ATTR_ORD_TIME' attr_value=:source_value | I31: org_units | J31: org_type | L31: users | M31: user_no
A32: 2025년 주요추진사업(NEW) | B32: 3 | C32: 계약시기 | D32: Y | E32: :source_value | F32: project_attributes | G32: attr_code='ATTR_CON_TIME' attr_value=:source_value | I32: org_units | J32: sort_order | L32: users | M32: login_id
A33: 2025년 주요추진사업(NEW) | B33: 3 | C33: 매출 | D33: N | I33: org_units | J33: is_use | L33: users | M33: password
A34: 2025년 주요추진사업(NEW) | B34: 3 | C34: 사업구도 ex) 마도 : OOO | D34: Y | E34: :source_value | F34: project_attributes | G34: attr_code='ATTR_BIZ_STR' attr_value=:source_value | I34: org_units | J34: created_at | L34: users | M34: user_name
A35: 2025년 주요추진사업(NEW) | B35: 3 | C35: 변동여부 | D35: Y | E35: :source_value | F35: project_attributes | G35: attr_code='ATTR_CHANGE' attr_value=:source_value | I35: org_units | J35: updated_at | L35: users | M35: role
A36: 2025년 주요추진사업(NEW) | B36: 3 | C36: - | D36: N | E36: :source_value | F36: project_history | G36: :source_value 내용을 파싱해서 라인의 시작부분에 일자가 형식이 있는 경우 해당일자를 base_date 일자 이후 라인의 내용을 strategy_content 에 insert ※기록된 일자 형익이 다양해서 인텔리전트하게 판단 필요 | I36: org_units | J36: created_by | L36: users | M36: is_sales_rep
A37: 2025년 주요추진사업(NEW) | B37: 3 | C37: 견적가(vat제외) | D37: Y | E37: :source_value | F37: projects | G37: quoted_amount | I37: org_units | J37: updated_by | L37: users | M37: email
A38: 2025년 주요추진사업(NEW) | B38: 3 | C38: 비고 | D38: Y | E38: :source_value | F38: projects | G38: notes | L38: users | M38: phone
A39: 2025년 주요추진사업(NEW) | B39: 3 | C39: 진행상황 및 영업전략(1) | D39: Y | E39: :source_value | F39: project_history | G39: :source_value 내용을 파싱해서 라인의 시작부분에 일자 형식이 있는 경우 해당일자를 base_date에 insert. 일자 이후 라인의 내용을 strategy_content 에 insert ※기록된 일자 형익이 다양해서 인텔리전트하게 판단 필요 | L39: users | M39: headquarters
A40: 2025년 주요추진사업(NEW) | B40: 3 | C40: 진행상황 및 영업전략(2) | D40: Y | E40: :source_value | F40: project_history | G40: :source_value 내용을 파싱해서 라인의 시작부분에 일자 형식이 있는 경우 해당일자를 base_date에 insert. 일자 이후 라인의 내용을 strategy_content 에 insert ※기록된 일자 형익이 다양해서 인텔리전트하게 판단 필요 | L40: users | M40: department
...

Sheet 26년 매출운영 현황
B2: ■ 2026년도 영업진행 및 계약 현황
B3: ※ 계약 고객사 파이프라인 ID 만 기입하세요(복사-붙여넣기) | O3: ※ 금액 단위 원. VAT별도
B4: 파이프라인 ID | C4: 분야 | D4: 고객사 | E4: 발주처 | F4: 사업명 | G4: 담당 | H4: 진행단계 | I4: 계약일자 | J4: 프로젝트 기간 | L4: 계약 | N4: 견적 제공 금액 | O4: 비고
J5: 시작 | K5: 종료 | L5: 수주금액 | M5: 계약금액
C6: =IF(ISERROR(VLOOKUP(B6,'2026년 주요추진사업'!C:W,2,FALSE)),"",VLOOKUP(B6,'2026년 주요추진사업'!C:W,2,FALSE)) | D6: =IF(ISERROR(VLOOKUP(B6,'2026년 주요추진사업'!C:W,3,FALSE)),"",VLOOKUP(B6,'2026년 주요추진사업'!C:W,3,FALSE)) | E6: =IF(ISERROR(VLOOKUP(B6,'2026년 주요추진사업'!C:W,4,FALSE)),"",VLOOKUP(B6,'2026년 주요추진사업'!C:W,4,FALSE)) | F6: =IF(ISERROR(VLOOKUP(B6,'2026년 주요추진사업'!C:W,5,FALSE)),"",VLOOKUP(B6,'2026년 주요추진사업'!C:W,5,FALSE)) | G6: =IF(ISERROR(VLOOKUP(B6,'2026년 주요추진사업'!C:W,6,FALSE)),"",VLOOKUP(B6,'2026년 주요추진사업'!C:W,6,FALSE)) | H6: =IF(ISERROR(VLOOKUP(B6,'2026년 주요추진사업'!C:W,7,FALSE)),"",VLOOKUP(B6,'2026년 주요추진사업'!C:W,7,FALSE)) | I6: =IF(ISERROR(VLOOKUP(B6,'2026년 주요추진사업'!C:W,13,FALSE)),"",VLOOKUP(B6,'2026년 주요추진사업'!C:W,13,FALSE)) | J6: =IF(ISERROR(VLOOKUP(B6,'2026년 주요추진사업'!C:W,14,FALSE)),"",VLOOKUP(B6,'2026년 주요추진사업'!C:W,14,FALSE)) | K6: =IF(ISERROR(VLOOKUP(B6,'2026년 주요추진사업'!C:W,15,FALSE)),"",VLOOKUP(B6,'2026년 주요추진사업'!C:W,15,FALSE)) | L6: =IF(ISERROR(VLOOKUP(B6,'2026년 주요추진사업'!C:W,16,FALSE)),"",VLOOKUP(B6,'2026년 주요추진사업'!C:W,16,FALSE)) | M6: =IF(ISERROR(VLOOKUP(B6,'2026년 주요추진사업'!C:W,17,FALSE)),"",VLOOKUP(B6,'2026년 주요추진사업'!C:W,17,FALSE)) | N6: =IF(ISERROR(VLOOKUP(B6,'2026년 주요추진사업'!C:W,10,FALSE)),"",VLOOKUP(B6,'2026년 주요추진사업'!C:W,10,FALSE))
C7: =IF(ISERROR(VLOOKUP(B7,'2026년 주요추진사업'!C:W,2,FALSE)),"",VLOOKUP(B7,'2026년 주요추진사업'!C:W,2,FALSE)) | D7: =IF(ISERROR(VLOOKUP(B7,'2026년 주요추진사업'!C:W,3,FALSE)),"",VLOOKUP(B7,'2026년 주요추진사업'!C:W,3,FALSE)) | E7: =IF(ISERROR(VLOOKUP(B7,'2026년 주요추진사업'!C:W,4,FALSE)),"",VLOOKUP(B7,'2026년 주요추진사업'!C:W,4,FALSE)) | F7: =IF(ISERROR(VLOOKUP(B7,'2026년 주요추진사업'!C:W,5,FALSE)),"",VLOOKUP(B7,'2026년 주요추진사업'!C:W,5,FALSE)) | G7: =IF(ISERROR(VLOOKUP(B7,'2026년 주요추진사업'!C:W,6,FALSE)),"",VLOOKUP(B7,'2026년 주요추진사업'!C:W,6,FALSE)) | H7: =IF(ISERROR(VLOOKUP(B7,'2026년 주요추진사업'!C:W,7,FALSE)),"",VLOOKUP(B7,'2026년 주요추진사업'!C:W,7,FALSE)) | I7: =IF(ISERROR(VLOOKUP(B7,'2026년 주요추진사업'!C:W,13,FALSE)),"",VLOOKUP(B7,'2026년 주요추진사업'!C:W,13,FALSE)) | J7: =IF(ISERROR(VLOOKUP(B7,'2026년 주요추진사업'!C:W,14,FALSE)),"",VLOOKUP(B7,'2026년 주요추진사업'!C:W,14,FALSE)) | K7: =IF(ISERROR(VLOOKUP(B7,'2026년 주요추진사업'!C:W,15,FALSE)),"",VLOOKUP(B7,'2026년 주요추진사업'!C:W,15,FALSE)) | L7: =IF(ISERROR(VLOOKUP(B7,'2026년 주요추진사업'!C:W,16,FALSE)),"",VLOOKUP(B7,'2026년 주요추진사업'!C:W,16,FALSE)) | M7: =IF(ISERROR(VLOOKUP(B7,'2026년 주요추진사업'!C:W,17,FALSE)),"",VLOOKUP(B7,'2026년 주요추진사업'!C:W,17,FALSE)) | N7: =IF(ISERROR(VLOOKUP(B7,'2026년 주요추진사업'!C:W,10,FALSE)),"",VLOOKUP(B7,'2026년 주요추진사업'!C:W,10,FALSE))
C8: =IF(ISERROR(VLOOKUP(B8,'2026년 주요추진사업'!C:W,2,FALSE)),"",VLOOKUP(B8,'2026년 주요추진사업'!C:W,2,FALSE)) | D8: =IF(ISERROR(VLOOKUP(B8,'2026년 주요추진사업'!C:W,3,FALSE)),"",VLOOKUP(B8,'2026년 주요추진사업'!C:W,3,FALSE)) | E8: =IF(ISERROR(VLOOKUP(B8,'2026년 주요추진사업'!C:W,4,FALSE)),"",VLOOKUP(B8,'2026년 주요추진사업'!C:W,4,FALSE)) | F8: =IF(ISERROR(VLOOKUP(B8,'2026년 주요추진사업'!C:W,5,FALSE)),"",VLOOKUP(B8,'2026년 주요추진사업'!C:W,5,FALSE)) | G8: =IF(ISERROR(VLOOKUP(B8,'2026년 주요추진사업'!C:W,6,FALSE)),"",VLOOKUP(B8,'2026년 주요추진사업'!C:W,6,FALSE)) | H8: =IF(ISERROR(VLOOKUP(B8,'2026년 주요추진사업'!C:W,7,FALSE)),"",VLOOKUP(B8,'2026년 주요추진사업'!C:W,7,FALSE)) | I8: =IF(ISERROR(VLOOKUP(B8,'2026년 주요추진사업'!C:W,13,FALSE)),"",VLOOKUP(B8,'2026년 주요추진사업'!C:W,13,FALSE)) | J8: =IF(ISERROR(VLOOKUP(B8,'2026년 주요추진사업'!C:W,14,FALSE)),"",VLOOKUP(B8,'2026년 주요추진사업'!C:W,14,FALSE)) | K8: =IF(ISERROR(VLOOKUP(B8,'2026년 주요추진사업'!C:W,15,FALSE)),"",VLOOKUP(B8,'2026년 주요추진사업'!C:W,15,FALSE)) | L8: =IF(ISERROR(VLOOKUP(B8,'2026년 주요추진사업'!C:W,16,FALSE)),"",VLOOKUP(B8,'2026년 주요추진사업'!C:W,16,FALSE)) | M8: =IF(ISERROR(VLOOKUP(B8,'2026년 주요추진사업'!C:W,17,FALSE)),"",VLOOKUP(B8,'2026년 주요추진사업'!C:W,17,FALSE)) | N8: =IF(ISERROR(VLOOKUP(B8,'2026년 주요추진사업'!C:W,10,FALSE)),"",VLOOKUP(B8,'2026년 주요추진사업'!C:W,10,FALSE))
C9: =IF(ISERROR(VLOOKUP(B9,'2026년 주요추진사업'!C:W,2,FALSE)),"",VLOOKUP(B9,'2026년 주요추진사업'!C:W,2,FALSE)) | D9: =IF(ISERROR(VLOOKUP(B9,'2026년 주요추진사업'!C:W,3,FALSE)),"",VLOOKUP(B9,'2026년 주요추진사업'!C:W,3,FALSE)) | E9: =IF(ISERROR(VLOOKUP(B9,'2026년 주요추진사업'!C:W,4,FALSE)),"",VLOOKUP(B9,'2026년 주요추진사업'!C:W,4,FALSE)) | F9: =IF(ISERROR(VLOOKUP(B9,'2026년 주요추진사업'!C:W,5,FALSE)),"",VLOOKUP(B9,'2026년 주요추진사업'!C:W,5,FALSE)) | G9: =IF(ISERROR(VLOOKUP(B9,'2026년 주요추진사업'!C:W,6,FALSE)),"",VLOOKUP(B9,'2026년 주요추진사업'!C:W,6,FALSE)) | H9: =IF(ISERROR(VLOOKUP(B9,'2026년 주요추진사업'!C:W,7,FALSE)),"",VLOOKUP(B9,'2026년 주요추진사업'!C:W,7,FALSE)) | I9: =IF(ISERROR(VLOOKUP(B9,'2026년 주요추진사업'!C:W,13,FALSE)),"",VLOOKUP(B9,'2026년 주요추진사업'!C:W,13,FALSE)) | J9: =IF(ISERROR(VLOOKUP(B9,'2026년 주요추진사업'!C:W,14,FALSE)),"",VLOOKUP(B9,'2026년 주요추진사업'!C:W,14,FALSE)) | K9: =IF(ISERROR(VLOOKUP(B9,'2026년 주요추진사업'!C:W,15,FALSE)),"",VLOOKUP(B9,'2026년 주요추진사업'!C:W,15,FALSE)) | L9: =IF(ISERROR(VLOOKUP(B9,'2026년 주요추진사업'!C:W,16,FALSE)),"",VLOOKUP(B9,'2026년 주요추진사업'!C:W,16,FALSE)) | M9: =IF(ISERROR(VLOOKUP(B9,'2026년 주요추진사업'!C:W,17,FALSE)),"",VLOOKUP(B9,'2026년 주요추진사업'!C:W,17,FALSE)) | N9: =IF(ISERROR(VLOOKUP(B9,'2026년 주요추진사업'!C:W,10,FALSE)),"",VLOOKUP(B9,'2026년 주요추진사업'!C:W,10,FALSE))
C10: =IF(ISERROR(VLOOKUP(B10,'2026년 주요추진사업'!C:W,2,FALSE)),"",VLOOKUP(B10,'2026년 주요추진사업'!C:W,2,FALSE)) | D10: =IF(ISERROR(VLOOKUP(B10,'2026년 주요추진사업'!C:W,3,FALSE)),"",VLOOKUP(B10,'2026년 주요추진사업'!C:W,3,FALSE)) | E10: =IF(ISERROR(VLOOKUP(B10,'2026년 주요추진사업'!C:W,4,FALSE)),"",VLOOKUP(B10,'2026년 주요추진사업'!C:W,4,FALSE)) | F10: =IF(ISERROR(VLOOKUP(B10,'2026년 주요추진사업'!C:W,5,FALSE)),"",VLOOKUP(B10,'2026년 주요추진사업'!C:W,5,FALSE)) | G10: =IF(ISERROR(VLOOKUP(B10,'2026년 주요추진사업'!C:W,6,FALSE)),"",VLOOKUP(B10,'2026년 주요추진사업'!C:W,6,FALSE)) | H10: =IF(ISERROR(VLOOKUP(B10,'2026년 주요추진사업'!C:W,7,FALSE)),"",VLOOKUP(B10,'2026년 주요추진사업'!C:W,7,FALSE)) | I10: =IF(ISERROR(VLOOKUP(B10,'2026년 주요추진사업'!C:W,13,FALSE)),"",VLOOKUP(B10,'2026년 주요추진사업'!C:W,13,FALSE)) | J10: =IF(ISERROR(VLOOKUP(B10,'2026년 주요추진사업'!C:W,14,FALSE)),"",VLOOKUP(B10,'2026년 주요추진사업'!C:W,14,FALSE)) | K10: =IF(ISERROR(VLOOKUP(B10,'2026년 주요추진사업'!C:W,15,FALSE)),"",VLOOKUP(B10,'2026년 주요추진사업'!C:W,15,FALSE)) | L10: =IF(ISERROR(VLOOKUP(B10,'2026년 주요추진사업'!C:W,16,FALSE)),"",VLOOKUP(B10,'2026년 주요추진사업'!C:W,16,FALSE)) | M10: =IF(ISERROR(VLOOKUP(B10,'2026년 주요추진사업'!C:W,17,FALSE)),"",VLOOKUP(B10,'2026년 주요추진사업'!C:W,17,FALSE)) | N10: =IF(ISERROR(VLOOKUP(B10,'2026년 주요추진사업'!C:W,10,FALSE)),"",VLOOKUP(B10,'2026년 주요추진사업'!C:W,10,FALSE))
C11: =IF(ISERROR(VLOOKUP(B11,'2026년 주요추진사업'!C:W,2,FALSE)),"",VLOOKUP(B11,'2026년 주요추진사업'!C:W,2,FALSE)) | D11: =IF(ISERROR(VLOOKUP(B11,'2026년 주요추진사업'!C:W,3,FALSE)),"",VLOOKUP(B11,'2026년 주요추진사업'!C:W,3,FALSE)) | E11: =IF(ISERROR(VLOOKUP(B11,'2026년 주요추진사업'!C:W,4,FALSE)),"",VLOOKUP(B11,'2026년 주요추진사업'!C:W,4,FALSE)) | F11: =IF(ISERROR(VLOOKUP(B11,'2026년 주요추진사업'!C:W,5,FALSE)),"",VLOOKUP(B11,'2026년 주요추진사업'!C:W,5,FALSE)) | G11: =IF(ISERROR(VLOOKUP(B11,'2026년 주요추진사업'!C:W,6,FALSE)),"",VLOOKUP(B11,'2026년 주요추진사업'!C:W,6,FALSE)) | H11: =IF(ISERROR(VLOOKUP(B11,'2026년 주요추진사업'!C:W,7,FALSE)),"",VLOOKUP(B11,'2026년 주요추진사업'!C:W,7,FALSE)) | I11: =IF(ISERROR(VLOOKUP(B11,'2026년 주요추진사업'!C:W,13,FALSE)),"",VLOOKUP(B11,'2026년 주요추진사업'!C:W,13,FALSE)) | J11: =IF(ISERROR(VLOOKUP(B11,'2026년 주요추진사업'!C:W,14,FALSE)),"",VLOOKUP(B11,'2026년 주요추진사업'!C:W,14,FALSE)) | K11: =IF(ISERROR(VLOOKUP(B11,'2026년 주요추진사업'!C:W,15,FALSE)),"",VLOOKUP(B11,'2026년 주요추진사업'!C:W,15,FALSE)) | L11: =IF(ISERROR(VLOOKUP(B11,'2026년 주요추진사업'!C:W,16,FALSE)),"",VLOOKUP(B11,'2026년 주요추진사업'!C:W,16,FALSE)) | M11: =IF(ISERROR(VLOOKUP(B11,'2026년 주요추진사업'!C:W,17,FALSE)),"",VLOOKUP(B11,'2026년 주요추진사업'!C:W,17,FALSE)) | N11: =IF(ISERROR(VLOOKUP(B11,'2026년 주요추진사업'!C:W,10,FALSE)),"",VLOOKUP(B11,'2026년 주요추진사업'!C:W,10,FALSE))
C12: =IF(ISERROR(VLOOKUP(B12,'2026년 주요추진사업'!C:W,2,FALSE)),"",VLOOKUP(B12,'2026년 주요추진사업'!C:W,2,FALSE)) | D12: =IF(ISERROR(VLOOKUP(B12,'2026년 주요추진사업'!C:W,3,FALSE)),"",VLOOKUP(B12,'2026년 주요추진사업'!C:W,3,FALSE)) | E12: =IF(ISERROR(VLOOKUP(B12,'2026년 주요추진사업'!C:W,4,FALSE)),"",VLOOKUP(B12,'2026년 주요추진사업'!C:W,4,FALSE)) | F12: =IF(ISERROR(VLOOKUP(B12,'2026년 주요추진사업'!C:W,5,FALSE)),"",VLOOKUP(B12,'2026년 주요추진사업'!C:W,5,FALSE)) | G12: =IF(ISERROR(VLOOKUP(B12,'2026년 주요추진사업'!C:W,6,FALSE)),"",VLOOKUP(B12,'2026년 주요추진사업'!C:W,6,FALSE)) | H12: =IF(ISERROR(VLOOKUP(B12,'2026년 주요추진사업'!C:W,7,FALSE)),"",VLOOKUP(B12,'2026년 주요추진사업'!C:W,7,FALSE)) | I12: =IF(ISERROR(VLOOKUP(B12,'2026년 주요추진사업'!C:W,13,FALSE)),"",VLOOKUP(B12,'2026년 주요추진사업'!C:W,13,FALSE)) | J12: =IF(ISERROR(VLOOKUP(B12,'2026년 주요추진사업'!C:W,14,FALSE)),"",VLOOKUP(B12,'2026년 주요추진사업'!C:W,14,FALSE)) | K12: =IF(ISERROR(VLOOKUP(B12,'2026년 주요추진사업'!C:W,15,FALSE)),"",VLOOKUP(B12,'2026년 주요추진사업'!C:W,15,FALSE)) | L12: =IF(ISERROR(VLOOKUP(B12,'2026년 주요추진사업'!C:W,16,FALSE)),"",VLOOKUP(B12,'2026년 주요추진사업'!C:W,16,FALSE)) | M12: =IF(ISERROR(VLOOKUP(B12,'2026년 주요추진사업'!C:W,17,FALSE)),"",VLOOKUP(B12,'2026년 주요추진사업'!C:W,17,FALSE)) | N12: =IF(ISERROR(VLOOKUP(B12,'2026년 주요추진사업'!C:W,10,FALSE)),"",VLOOKUP(B12,'2026년 주요추진사업'!C:W,10,FALSE))
C13: =IF(ISERROR(VLOOKUP(B13,'2026년 주요추진사업'!C:W,2,FALSE)),"",VLOOKUP(B13,'2026년 주요추진사업'!C:W,2,FALSE)) | D13: =IF(ISERROR(VLOOKUP(B13,'2026년 주요추진사업'!C:W,3,FALSE)),"",VLOOKUP(B13,'2026년 주요추진사업'!C:W,3,FALSE)) | E13: =IF(ISERROR(VLOOKUP(B13,'2026년 주요추진사업'!C:W,4,FALSE)),"",VLOOKUP(B13,'2026년 주요추진사업'!C:W,4,FALSE)) | F13: =IF(ISERROR(VLOOKUP(B13,'2026년 주요추진사업'!C:W,5,FALSE)),"",VLOOKUP(B13,'2026년 주요추진사업'!C:W,5,FALSE)) | G13: =IF(ISERROR(VLOOKUP(B13,'2026년 주요추진사업'!C:W,6,FALSE)),"",VLOOKUP(B13,'2026년 주요추진사업'!C:W,6,FALSE)) | H13: =IF(ISERROR(VLOOKUP(B13,'2026년 주요추진사업'!C:W,7,FALSE)),"",VLOOKUP(B13,'2026년 주요추진사업'!C:W,7,FALSE)) | I13: =IF(ISERROR(VLOOKUP(B13,'2026년 주요추진사업'!C:W,13,FALSE)),"",VLOOKUP(B13,'2026년 주요추진사업'!C:W,13,FALSE)) | J13: =IF(ISERROR(VLOOKUP(B13,'2026년 주요추진사업'!C:W,14,FALSE)),"",VLOOKUP(B13,'2026년 주요추진사업'!C:W,14,FALSE)) | K13: =IF(ISERROR(VLOOKUP(B13,'2026년 주요추진사업'!C:W,15,FALSE)),"",VLOOKUP(B13,'2026년 주요추진사업'!C:W,15,FALSE)) | L13: =IF(ISERROR(VLOOKUP(B13,'2026년 주요추진사업'!C:W,16,FALSE)),"",VLOOKUP(B13,'2026년 주요추진사업'!C:W,16,FALSE)) | M13: =IF(ISERROR(VLOOKUP(B13,'2026년 주요추진사업'!C:W,17,FALSE)),"",VLOOKUP(B13,'2026년 주요추진사업'!C:W,17,FALSE)) | N13: =IF(ISERROR(VLOOKUP(B13,'2026년 주요추진사업'!C:W,10,FALSE)),"",VLOOKUP(B13,'2026년 주요추진사업'!C:W,10,FALSE))
C14: =IF(ISERROR(VLOOKUP(B14,'2026년 주요추진사업'!C:W,2,FALSE)),"",VLOOKUP(B14,'2026년 주요추진사업'!C:W,2,FALSE)) | D14: =IF(ISERROR(VLOOKUP(B14,'2026년 주요추진사업'!C:W,3,FALSE)),"",VLOOKUP(B14,'2026년 주요추진사업'!C:W,3,FALSE)) | E14: =IF(ISERROR(VLOOKUP(B14,'2026년 주요추진사업'!C:W,4,FALSE)),"",VLOOKUP(B14,'2026년 주요추진사업'!C:W,4,FALSE)) | F14: =IF(ISERROR(VLOOKUP(B14,'2026년 주요추진사업'!C:W,5,FALSE)),"",VLOOKUP(B14,'2026년 주요추진사업'!C:W,5,FALSE)) | G14: =IF(ISERROR(VLOOKUP(B14,'2026년 주요추진사업'!C:W,6,FALSE)),"",VLOOKUP(B14,'2026년 주요추진사업'!C:W,6,FALSE)) | H14: =IF(ISERROR(VLOOKUP(B14,'2026년 주요추진사업'!C:W,7,FALSE)),"",VLOOKUP(B14,'2026년 주요추진사업'!C:W,7,FALSE)) | I14: =IF(ISERROR(VLOOKUP(B14,'2026년 주요추진사업'!C:W,13,FALSE)),"",VLOOKUP(B14,'2026년 주요추진사업'!C:W,13,FALSE)) | J14: =IF(ISERROR(VLOOKUP(B14,'2026년 주요추진사업'!C:W,14,FALSE)),"",VLOOKUP(B14,'2026년 주요추진사업'!C:W,14,FALSE)) | K14: =IF(ISERROR(VLOOKUP(B14,'2026년 주요추진사업'!C:W,15,FALSE)),"",VLOOKUP(B14,'2026년 주요추진사업'!C:W,15,FALSE)) | L14: =IF(ISERROR(VLOOKUP(B14,'2026년 주요추진사업'!C:W,16,FALSE)),"",VLOOKUP(B14,'2026년 주요추진사업'!C:W,16,FALSE)) | M14: =IF(ISERROR(VLOOKUP(B14,'2026년 주요추진사업'!C:W,17,FALSE)),"",VLOOKUP(B14,'2026년 주요추진사업'!C:W,17,FALSE)) | N14: =IF(ISERROR(VLOOKUP(B14,'2026년 주요추진사업'!C:W,10,FALSE)),"",VLOOKUP(B14,'2026년 주요추진사업'!C:W,10,FALSE))
C15: =IF(ISERROR(VLOOKUP(B15,'2026년 주요추진사업'!C:W,2,FALSE)),"",VLOOKUP(B15,'2026년 주요추진사업'!C:W,2,FALSE)) | D15: =IF(ISERROR(VLOOKUP(B15,'2026년 주요추진사업'!C:W,3,FALSE)),"",VLOOKUP(B15,'2026년 주요추진사업'!C:W,3,FALSE)) | E15: =IF(ISERROR(VLOOKUP(B15,'2026년 주요추진사업'!C:W,4,FALSE)),"",VLOOKUP(B15,'2026년 주요추진사업'!C:W,4,FALSE)) | F15: =IF(ISERROR(VLOOKUP(B15,'2026년 주요추진사업'!C:W,5,FALSE)),"",VLOOKUP(B15,'2026년 주요추진사업'!C:W,5,FALSE)) | G15: =IF(ISERROR(VLOOKUP(B15,'2026년 주요추진사업'!C:W,6,FALSE)),"",VLOOKUP(B15,'2026년 주요추진사업'!C:W,6,FALSE)) | H15: =IF(ISERROR(VLOOKUP(B15,'2026년 주요추진사업'!C:W,7,FALSE)),"",VLOOKUP(B15,'2026년 주요추진사업'!C:W,7,FALSE)) | I15: =IF(ISERROR(VLOOKUP(B15,'2026년 주요추진사업'!C:W,13,FALSE)),"",VLOOKUP(B15,'2026년 주요추진사업'!C:W,13,FALSE)) | J15: =IF(ISERROR(VLOOKUP(B15,'2026년 주요추진사업'!C:W,14,FALSE)),"",VLOOKUP(B15,'2026년 주요추진사업'!C:W,14,FALSE)) | K15: =IF(ISERROR(VLOOKUP(B15,'2026년 주요추진사업'!C:W,15,FALSE)),"",VLOOKUP(B15,'2026년 주요추진사업'!C:W,15,FALSE)) | L15: =IF(ISERROR(VLOOKUP(B15,'2026년 주요추진사업'!C:W,16,FALSE)),"",VLOOKUP(B15,'2026년 주요추진사업'!C:W,16,FALSE)) | M15: =IF(ISERROR(VLOOKUP(B15,'2026년 주요추진사업'!C:W,17,FALSE)),"",VLOOKUP(B15,'2026년 주요추진사업'!C:W,17,FALSE)) | N15: =IF(ISERROR(VLOOKUP(B15,'2026년 주요추진사업'!C:W,10,FALSE)),"",VLOOKUP(B15,'2026년 주요추진사업'!C:W,10,FALSE))
C16: =IF(ISERROR(VLOOKUP(B16,'2026년 주요추진사업'!C:W,2,FALSE)),"",VLOOKUP(B16,'2026년 주요추진사업'!C:W,2,FALSE)) | D16: =IF(ISERROR(VLOOKUP(B16,'2026년 주요추진사업'!C:W,3,FALSE)),"",VLOOKUP(B16,'2026년 주요추진사업'!C:W,3,FALSE)) | E16: =IF(ISERROR(VLOOKUP(B16,'2026년 주요추진사업'!C:W,4,FALSE)),"",VLOOKUP(B16,'2026년 주요추진사업'!C:W,4,FALSE)) | F16: =IF(ISERROR(VLOOKUP(B16,'2026년 주요추진사업'!C:W,5,FALSE)),"",VLOOKUP(B16,'2026년 주요추진사업'!C:W,5,FALSE)) | G16: =IF(ISERROR(VLOOKUP(B16,'2026년 주요추진사업'!C:W,6,FALSE)),"",VLOOKUP(B16,'2026년 주요추진사업'!C:W,6,FALSE)) | H16: =IF(ISERROR(VLOOKUP(B16,'2026년 주요추진사업'!C:W,7,FALSE)),"",VLOOKUP(B16,'2026년 주요추진사업'!C:W,7,FALSE)) | I16: =IF(ISERROR(VLOOKUP(B16,'2026년 주요추진사업'!C:W,13,FALSE)),"",VLOOKUP(B16,'2026년 주요추진사업'!C:W,13,FALSE)) | J16: =IF(ISERROR(VLOOKUP(B16,'2026년 주요추진사업'!C:W,14,FALSE)),"",VLOOKUP(B16,'2026년 주요추진사업'!C:W,14,FALSE)) | K16: =IF(ISERROR(VLOOKUP(B16,'2026년 주요추진사업'!C:W,15,FALSE)),"",VLOOKUP(B16,'2026년 주요추진사업'!C:W,15,FALSE)) | L16: =IF(ISERROR(VLOOKUP(B16,'2026년 주요추진사업'!C:W,16,FALSE)),"",VLOOKUP(B16,'2026년 주요추진사업'!C:W,16,FALSE)) | M16: =IF(ISERROR(VLOOKUP(B16,'2026년 주요추진사업'!C:W,17,FALSE)),"",VLOOKUP(B16,'2026년 주요추진사업'!C:W,17,FALSE)) | N16: =IF(ISERROR(VLOOKUP(B16,'2026년 주요추진사업'!C:W,10,FALSE)),"",VLOOKUP(B16,'2026년 주요추진사업'!C:W,10,FALSE))
C17: =IF(ISERROR(VLOOKUP(B17,'2026년 주요추진사업'!C:W,2,FALSE)),"",VLOOKUP(B17,'2026년 주요추진사업'!C:W,2,FALSE)) | D17: =IF(ISERROR(VLOOKUP(B17,'2026년 주요추진사업'!C:W,3,FALSE)),"",VLOOKUP(B17,'2026년 주요추진사업'!C:W,3,FALSE)) | E17: =IF(ISERROR(VLOOKUP(B17,'2026년 주요추진사업'!C:W,4,FALSE)),"",VLOOKUP(B17,'2026년 주요추진사업'!C:W,4,FALSE)) | F17: =IF(ISERROR(VLOOKUP(B17,'2026년 주요추진사업'!C:W,5,FALSE)),"",VLOOKUP(B17,'2026년 주요추진사업'!C:W,5,FALSE)) | G17: =IF(ISERROR(VLOOKUP(B17,'2026년 주요추진사업'!C:W,6,FALSE)),"",VLOOKUP(B17,'2026년 주요추진사업'!C:W,6,FALSE)) | H17: =IF(ISERROR(VLOOKUP(B17,'2026년 주요추진사업'!C:W,7,FALSE)),"",VLOOKUP(B17,'2026년 주요추진사업'!C:W,7,FALSE)) | I17: =IF(ISERROR(VLOOKUP(B17,'2026년 주요추진사업'!C:W,13,FALSE)),"",VLOOKUP(B17,'2026년 주요추진사업'!C:W,13,FALSE)) | J17: =IF(ISERROR(VLOOKUP(B17,'2026년 주요추진사업'!C:W,14,FALSE)),"",VLOOKUP(B17,'2026년 주요추진사업'!C:W,14,FALSE)) | K17: =IF(ISERROR(VLOOKUP(B17,'2026년 주요추진사업'!C:W,15,FALSE)),"",VLOOKUP(B17,'2026년 주요추진사업'!C:W,15,FALSE)) | L17: =IF(ISERROR(VLOOKUP(B17,'2026년 주요추진사업'!C:W,16,FALSE)),"",VLOOKUP(B17,'2026년 주요추진사업'!C:W,16,FALSE)) | M17: =IF(ISERROR(VLOOKUP(B17,'2026년 주요추진사업'!C:W,17,FALSE)),"",VLOOKUP(B17,'2026년 주요추진사업'!C:W,17,FALSE)) | N17: =IF(ISERROR(VLOOKUP(B17,'2026년 주요추진사업'!C:W,10,FALSE)),"",VLOOKUP(B17,'2026년 주요추진사업'!C:W,10,FALSE))
... C119: =IF(ISERROR(VLOOKUP(B119,'2026년 주요추진사업'!C:W,2,FALSE)),"",VLOOKUP(B119,'2026년 주요추진사업'!C:W,2,FALSE)) | D119: =IF(ISERROR(VLOOKUP(B119,'2026년 주요추진사업'!C:W,3,FALSE)),"",VLOOKUP(B119,'2026년 주요추진사업'!C:W,3,FALSE)) | E119: =IF(ISERROR(VLOOKUP(B119,'2026년 주요추진사업'!C:W,4,FALSE)),"",VLOOKUP(B119,'2026년 주요추진사업'!C:W,4,FALSE)) | F119: =IF(ISERROR(VLOOKUP(B119,'2026년 주요추진사업'!C:W,5,FALSE)),"",VLOOKUP(B119,'2026년 주요추진사업'!C:W,5,FALSE)) | G119: =IF(ISERROR(VLOOKUP(B119,'2026년 주요추진사업'!C:W,6,FALSE)),"",VLOOKUP(B119,'2026년 주요추진사업'!C:W,6,FALSE)) | H119: =IF(ISERROR(VLOOKUP(B119,'2026년 주요추진사업'!C:W,7,FALSE)),"",VLOOKUP(B119,'2026년 주요추진사업'!C:W,7,FALSE)) | I119: =IF(ISERROR(VLOOKUP(B119,'2026년 주요추진사업'!C:W,13,FALSE)),"",VLOOKUP(B119,'2026년 주요추진사업'!C:W,13,FALSE)) | J119: =IF(ISERROR(VLOOKUP(B119,'2026년 주요추진사업'!C:W,14,FALSE)),"",VLOOKUP(B119,'2026년 주요추진사업'!C:W,14,FALSE)) | K119: =IF(ISERROR(VLOOKUP(B119,'2026년 주요추진사업'!C:W,15,FALSE)),"",VLOOKUP(B119,'2026년 주요추진사업'!C:W,15,FALSE)) | L119: =IF(ISERROR(VLOOKUP(B119,'2026년 주요추진사업'!C:W,16,FALSE)),"",VLOOKUP(B119,'2026년 주요추진사업'!C:W,16,FALSE)) | M119: =IF(ISERROR(VLOOKUP(B119,'2026년 주요추진사업'!C:W,17,FALSE)),"",VLOOKUP(B119,'2026년 주요추진사업'!C:W,17,FALSE)) | N119: =IF(ISERROR(VLOOKUP(B119,'2026년 주요추진사업'!C:W,10,FALSE)),"",VLOOKUP(B119,'2026년 주요추진사업'!C:W,10,FALSE))
H121: 합계 | L121: =SUM(L6:L119) -> 0 | M121: =SUM(M6:M119) -> 0

Sheet 2026년 주요추진사업
B1: 2026년도 신사업개발/엔터프라이즈컨설팅팀 주요사업 추진 내역
B2: ※ 작성법: 담당 고객사 위에 행 삽입 후 복사-붙여넣기. 업무기준일~진행상황 및 영업전략 작성.
B3: 주차 | C3: 파이프라인 ID | D3: 분야 | E3: 고객사 | F3: 발주처 | G3: 사업명 | H3: 담당자 | I3: 진행단계 | J3: 업무 기준일 | K3: 진행상황 및 영업전략 | L3: 견적금액 단위 원. VAT제외 | M3: 발주시기(예상) | N3: 계약시기(예상) | O3: 계약일자 | P3: 프로젝트기간(시작) | Q3: 프로젝트기간(종료) | R3: 계약(수주금액) 단위 원. VAT제외 | S3: 계약(계약금액) 단위 원. VAT제외 | T3: 매출 | U3: 사업구도 ex) 마도 : OOO | V3: 이전 파이프라인 | W3: 비고
B4: =IF(ISERROR(VLOOKUP(J4,'==='!B:E,4,FALSE)),"",VLOOKUP(J4,'==='!B:E,4,FALSE)) -> 1월 2주 | C4: 2026-014 | D4: AICC | E4: 경찰청 | F4: 펜타시스템 | G4: 경찰청 경찰견문관리시스템 고도화 사업(STT) | H4: 오민규 | I4: 7 수주완료 | J4: 46036 | K4: - PJT 시작일정: 5~6월 예상 (※ 발주 3~4월) . STT 솔루션 타사 견적 확인중(사운드마인드) | V4: 2025-065
B5: =IF(ISERROR(VLOOKUP(J5,'==='!B:E,4,FALSE)),"",VLOOKUP(J5,'==='!B:E,4,FALSE)) -> 1월 2주 | C5: 2026-016 | D5: 수어 | E5: 국립인천해양박물관 | F5: 국립인천해양박물관 | G5: 국립인천해양박물관 안내 및 전시정보 영상 제작 | H5: 양승구 | I5: 2 견적제출 | J5: 46036 | K5: 국립인천해양박물관 - 박물관 안내 및 전시정보스포츠안전관련 홍보팀 업무 담당 - 디지털미디어부 학예연구사 님과 협의 후 견적서 제출 (27년도 예산 산출) - 표준 견적서 제출 후 문구 확정하면 최종 견적서 제공 - 수어 인식율에 대한 문의 (현재 미약함 - 60%정도, 현재 연구 중이며, 개선 진행 중) | L5: 132000 | M5: 12월 | U5: 단독
B6: =IF(ISERROR(VLOOKUP(J6,'==='!B:E,4,FALSE)),"",VLOOKUP(J6,'==='!B:E,4,FALSE)) -> 2월 1주 | C6: 2026-015 | D6: 수어 | E6: 국민체육진흥공단 | F6: 국민체육진흥공단 | G6: 국민체육진흥공단 체육시설 안전 홍보 안내 AI수어 아바타 영상 제작 | H6: 임철현 | I6: 1 영업중 | J6: 46056 | K6: 국민체육진흥공단 스포츠시설안전실 안전교육팀 김수빈대리 통화 - 타업무로 인하여 내부 스포츠안전 영상관련 우선순위 선정 및 관련농인 인터뷰 업무 지연, 차주 진행사항 체크 예정
B7: =IF(ISERROR(VLOOKUP(J7,'==='!B:E,4,FALSE)),"",VLOOKUP(J7,'==='!B:E,4,FALSE)) -> 1월 3주 | C7: 2026-015 | D7: 수어 | E7: 국민체육진흥공단 | F7: 국민체육진흥공단 | G7: 국민체육진흥공단 체육시설 안전 홍보 안내 AI수어 아바타 영상 제작 | H7: 임철현 | I7: 1 영업중 | J7: 46043 | K7: 국민체육진흥공단 스포츠시설안전실 안전교육팀 김수빈대리 통화 - 스포츠안전관련 내부 보고관련 기획안 제공 - 내부 스포츠안전 영상관련 우선순위 선정 및 관련농인 인터뷰등 진행예정, 2월초 진행사항관련 재협의 하기로 함
B8: =IF(ISERROR(VLOOKUP(J8,'==='!B:E,4,FALSE)),"",VLOOKUP(J8,'==='!B:E,4,FALSE)) -> 1월 2주 | C8: 2026-015 | D8: 수어 | E8: 국민체육진흥공단 | F8: 국민체육진흥공단 | G8: 국민체육진흥공단 체육시설 안전 홍보 안내 AI수어 아바타 영상 제작 | H8: 임철현 | I8: 1 영업중 | J8: 46036 | K8: 국민체육진흥공단 스포츠시설안전실 안전교육팀 김수빈대리 미팅 - 스포츠안전관련 홍보팀 업무 담당 - 공단내 스포츠안전관련 홍보영상 다수 보유 중이며 국정과제 기반 기 홍보중인 영상에 Ai수어아바타 서비스를 적용하는 시범서비스 계획중 - 홍보예산 1.4억 중 일부(2~3천만원)를 명확하게 금액을 얘기 하진 않음, 기보유 홍보영상 3~5개에 수어아바타 시범 적용을 계획 L 차주 월요일까지 내부 보고관련 기획안 제공을 제안드림
B9: =IF(ISERROR(VLOOKUP(J9,'==='!B:E,4,FALSE)),"",VLOOKUP(J9,'==='!B:E,4,FALSE)) -> 1월 2주 | C9: 2026-018 | D9: 수어 | E9: 남양주수어통역센터 | F9: 남양주수어통역센터 | G9: 남양주수어통역센터 당사 핸드사인톡톡 입정 협의 | H9: 양승구 | I9: 3 제안중 | J9: 46036 | K9: 남양주시수어통역센터 "당사 핸드사인툭툭 입정"에 따른 공문 발송 - 담당자 공분 수보 완료, 내부 검토 후 진행에 대한 협의예정 (1.16일 전화 연럭 후 확인)
C10: 2026-018 | D10: 수어 | E10: 남양주수어통역센터 | F10: 남양주수어통역센터 | G10: 남양주수어통역센터 당사 핸드사인톡톡 입정 협의 | H10: 양승구 | I10: 3 제안중 | J10: 46043 | K10: 남양주시수어통역센터 담당자님 이직에 따른 남양주시 시각장애인협회 센터장님 미팅 - 당사 소개 및 추후 시각장애인을 위한 사업 진행시 조언 요청 (적극 지원 하겠음 - 당사 서울 120다산콜재단 사업 진행시 조언 요청 하겠음)
B11: =IF(ISERROR(VLOOKUP(J11,'==='!B:E,4,FALSE)),"",VLOOKUP(J11,'==='!B:E,4,FALSE)) -> 1월 2주 | C11: 2026-016 | D11: 수어 | E11: 남양주시청 | F11: 남양주시청 홍보과 | G11: 남양주시청 시장님 신년인사에 AI수어 구축 | H11: 양승구 | I11: 6 실주 | J11: 46036 | K11: AI 수어를 일반 수어통역사를 통해서 사업을 진행하는 것으로 변경 - 16어절 당사 300만원, 일반 수어통역사 비용 - 30만원 사유로 일반통역사의 촬영으로 사업 변경하여 진향
B12: =IF(ISERROR(VLOOKUP(J12,'==='!B:E,4,FALSE)),"",VLOOKUP(J12,'==='!B:E,4,FALSE)) -> 1월 2주 | C12: 2026-001 | D12: AICC | E12: 모던텍 | F12: 모던텍 | G12: 모던텍 음성봇(SaaS) 도입 및 고객센터 운영 | H12: 오민규 | I12: 3 제안중 | J12: 46031 | K12: - 담당자 미팅 : 1/8 조원부장 . 전체적인 비용효과가 크지 않아 추진 부정적(5개년 52백만원 ↓) . 현 상담센터 최저가 운영중. 최근 충전기 고장/오류 통합관리시스템 오픈으로 운영 애로사항 많이 개선됨 . 초기 검토시 퀄리티&비용효율화 도모하였으나, 비용 최우선으로 검토중 . 결제, 고장신고 등의 클레임성 고객 전화로 AI보다는 상담사 직접 대응이 효율적으로 판단됨 | V12: 2025-104
B13: =IF(ISERROR(VLOOKUP(J13,'==='!B:E,4,FALSE)),"",VLOOKUP(J13,'==='!B:E,4,FALSE)) -> 1월 2주 | C13: 2026-019 | D13: 수어 | E13: 법원행정처 | F13: 법원행정처 | G13: 법원행정처 교육자료 AI 수어영상 제작 | H13: 양승구 | I13: 1 영업중 | J13: 46037 | K13: 기 구축한 "법정수어통역 표준 교육자료 발간을 위한 수어영상 제작" 사용에 대한 문의 - 당사 AI 수어서비스의 제안 및 수어용어집 진행 가능성에 댜헌 협의
B14: =IF(ISERROR(VLOOKUP(J14,'==='!B:E,4,FALSE)),"",VLOOKUP(J14,'==='!B:E,4,FALSE)) -> 2월 1주 | C14: 2026-005 | D14: 수어 | E14: 식품안전정보원 | F14: 식품안전정보원 | G14: 식품안전정보원 실시간 식품정보 수어 영상 제공 프로그램 개발 용역 | H14: 임철현 | I14: 4 입찰중 | J14: 46055 | K14: - 기술협상대상자 선정 확인 - 02.05. 14:00 기술협상 진행예정 | L14: =49950000/1.1 -> 45409091 | M14: 1월 | N14: 1월 말 또는 2월 초 | P14: 계약일 | Q14: 46203 | U14: 주관사 | V14: 2025-117
B15: =IF(ISERROR(VLOOKUP(J15,'==='!B:E,4,FALSE)),"",VLOOKUP(J15,'==='!B:E,4,FALSE)) -> 1월 4주 | C15: 2026-005 | D15: 수어 | E15: 식품안전정보원 | F15: 식품안전정보원 | G15: 식품안전정보원 실시간 식품정보 수어 영상 제공 프로그램 개발 용역 | H15: 임철현 | I15: 3 제안중 | J15: 46051 | K15: - 01/29 제안발표관련 (발표자: 허길량부장, 동석자: 이하형팀장,임철현) L 14:50분부터 발표 L 3개사 참여 확인, 당사 발표 - 01/28 제안발표관련 최종 리뷰(허길량대표, 이하형팀장) | M15: 1월 | N15: 1월 말 또는 2월 초 | P15: 계약일 | Q15: 46203 | U15: 주관사 | V15: 2025-117
B16: =IF(ISERROR(VLOOKUP(J16,'==='!B:E,4,FALSE)),"",VLOOKUP(J16,'==='!B:E,4,FALSE)) -> 1월 3주 | C16: 2026-005 | D16: 수어 | E16: 식품안전정보원 | F16: 식품안전정보원 | G16: 식품안전정보원 실시간 식품정보 수어 영상 제공 프로그램 개발 용역 | H16: 임철현 | I16: 3 제안중 | J16: 46043 | K16: - 01/21 제안발표관련 1차 리뷰(허길량대표, 이하형팀장) L 발표자료관련 당사 강점 설명 및 발표시 전략등 협의 L 차주 월요일 또는 화요일 2차 리뷰 진행 협의 L 제안발표장 참석자(안): 허길양(PM), 이하형팀장, 임철현 | M16: 1월 | N16: 1월 말 또는 2월 초 | P16: 계약일 | Q16: 46203 | U16: 주관사 | V16: 2025-117
B17: =IF(ISERROR(VLOOKUP(J17,'==='!B:E,4,FALSE)),"",VLOOKUP(J17,'==='!B:E,4,FALSE)) -> 1월 2주 | C17: 2026-005 | D17: 수어 | E17: 식품안전정보원 | F17: 식품안전정보원 | G17: 식품안전정보원 실시간 식품정보 수어 영상 제공 프로그램 개발 용역 | H17: 임철현 | I17: 3 제안중 | J17: 46037 | K17: - 01-14 제안서 작성관련 제안팀 및 협력사(허시정보) 미팅 진행/ 참석자: 김태형, 고윤창, 김해밝음, 백승준, 임철현, 허시정보(허길양대표) L 제안서 기술파트 및 발표자료 허시정보 작성, 그외 파트 사업제안팀 작성, 1차 완료 16일까지 진행 - 01-15 고객사(임현수 선임연구원) 미팅 w 허길양 L RFP관련 문의 및 정보 취득, 고객사 금번 사업외 향후 사업 발전방안(식품표시정보 수정영상등 활용)에 대해서도 제안 요청 접수 L 경쟁사(멀틱스)관련 정보 취득, 제안서 작성관련 문의 있었다고 함. | M17: 1월 | N17: 1월 말 또는 2월 초 | P17: 계약일 | Q17: 46203 | U17: 주관사 | V17: 2025-117
B18: =IF(ISERROR(VLOOKUP(J18,'==='!B:E,4,FALSE)),"",VLOOKUP(J18,'==='!B:E,4,FALSE)) -> 1월 2주 | C18: 2026-005 | D18: 수어 | E18: 식품안전정보원 | F18: 식품안전정보원 | G18: 식품안전정보원 실시간 식품정보 수어 영상 제공 프로그램 개발 용역 | H18: 임철현 | I18: 3 제안중 | J18: 46035 | K18: - 입찰공고: 01/06 공동수급(마감): 01/19 18:00까지 제안마감: 01/20 10:00 -> 단독 제안 및 제안전략관련 고객사 미팅 | M18: 1월 | N18: 1월 말 또는 2월 초 | P18: 계약일 | Q18: 46203 | U18: 주관사 | V18: 2025-117
B19: =IF(ISERROR(VLOOKUP(J19,'==='!B:E,4,FALSE)),"",VLOOKUP(J19,'==='!B:E,4,FALSE)) -> 1월 2주 | C19: 2026-004 | D19: AICC | E19: 티플리스 | F19: - | G19: 티플리스 공공기관, 지자체 AICC. MOU | H19: 오민규 | I19: 1 영업중 | J19: 46037 | K19: - 차주 미팅 예정(김동훈그룹장 외. 일정 미정) | V19: -
B20: =IF(ISERROR(VLOOKUP(J20,'==='!B:E,4,FALSE)),"",VLOOKUP(J20,'==='!B:E,4,FALSE)) -> 2월 1주 | C20: 2026-013 | D20: 수어 | E20: 현성컨버전스 | F20: 현성컨버전스 | G20: 현성컨버전스 엘리베이터 비상통화장치 수어서비스 | H20: 임철현 | I20: 1 영업중 | J20: 46056 | K20: 현성컨버전스 김정록팀장, 김용호연구소장 미팅 L 비상통화장치기기내 카메라로 수어인식 문제점 설명 및 당사 롤기반 수어봇 기술 제안 협의 L 개발팀 경유 당사 수어봇 HW적정스펙 공유 예정 L 승강기공단(김희석과장) 현재상황관련 설명 및 기술자료 제공, 내부 검토후 이견있을경우 재통화 하기로 함
B21: =IF(ISERROR(VLOOKUP(J21,'==='!B:E,4,FALSE)),"",VLOOKUP(J21,'==='!B:E,4,FALSE)) -> 1월 4주 | C21: 2026-013 | D21: 수어 | E21: 현성컨버전스 | F21: 현성컨버전스 | G21: 현성컨버전스 엘리베이터 비상통화장치 수어서비스 | H21: 임철현 | I21: 1 영업중 | J21: 46051 | K21: 전략기획실 미팅(김민선, 안혜신, 임철현) L 현성컨버전스 및 승강기안전공단 제안 기술(비상통화장치기기내 카메라로 수어인식)에 대한 문제점 자료 준비 및 당사 롤기반 수어봇 기술 제안 협의 L 개발팀 기술자료 준비시 차주 화, 수중 현성컨버전스 영업과 협의 진행 예정
B22: =IF(ISERROR(VLOOKUP(J22,'==='!B:E,4,FALSE)),"",VLOOKUP(J22,'==='!B:E,4,FALSE)) -> 1월 2주 | C22: 2026-013 | D22: 수어 | E22: 현성컨버전스 | F22: 현성컨버전스 | G22: 현성컨버전스 엘리베이터 비상통화장치 수어서비스 | H22: 임철현 | I22: 1 영업중 | J22: 46035 | K22: 현성컨버전스 대표이사, 연구소장, 영업팀장 미팅 - 현성컨버전스에서 엘리베이터 비상통화장치 KC 안전 인증 취득(25.07.07) - 자체 비상통화장치에 시청각 장애인을 위한 수어 및 음성서비스 고려 중 L 현황: 엘리베이터에 설치된 비상통화장치에 있는 카메라(화소: 2M픽셀)를 통해 수어 인식-> 음성으로 전환하여 상황실 화상전화기로 전달 되는 방식을 구상 중임 -> 당사 룰베이스 기반 수어봇으로 서비스 전환을 제안 및 비상상황에 대한 질의응답 사례 수집 요청 함/ 당사 제안에 대해 내부 검토 하기로 함. 당사 기술팀에서도 카메라를 통한 실시간 수어인식 및 상황실로 음성전달 가능 여부 확인 하기로 함 이슈사항: 현성의 비상통화서비스는 Server-Client 구성으로 제안중에 있으며 1Server에 100 ~ 1,000대의 비상통화장치 연결이 가능 하다고 함 비상통화장치 시장은 대당 3만원 대로 공급되고 있으나, 현성은 조금더 고가로 시장인식 있다고 함. 이에 대해 비상통화장치외 서버비용을 임대형식으로 제안공급 중 임 당사 수어서비스 적용시 원가 상승에 대한 고민 있으나 당사와의 협업을 하고자 함
B23: =IF(ISERROR(VLOOKUP(J23,'==='!B:E,4,FALSE)),"",VLOOKUP(J23,'==='!B:E,4,FALSE)) -> 1월 2주 | C23: 2026-010 | D23: 수어 | E23: KB국민은행 | F23: KB국민은행 | G23: KB국민은행 AI 수어 상담에 대한 챗봇 연계 구축 | H23: 양승구 | I23: 3 제안중 | J23: 46037 | K23: 본 프로젝트 담당자 소개 및 사업의 진행 방향 협의 - 사업의 진행이 느리지만 시작 예정(1월초 --> 설 이후) , 지속적인 협의 진행 | V23: 2025-084
B24: =IF(ISERROR(VLOOKUP(J24,'==='!B:E,4,FALSE)),"",VLOOKUP(J24,'==='!B:E,4,FALSE)) -> 1월 1주 | C24: 2026-002 | D24: 수어 | E24: (주)서원 | F24: (주)서원 | G24: (주)서원 고속도록 휴게소 배리어프리 무인발권기 도입사업 | H24: 오민규 | I24: 1 영업중 | J24: 46028 | K24: - 담당자 연락 : 임재현팀장(퇴사함) . 2025년 7월 선산휴게소 사업 제안시 당사 수어 제안하였으나 실주함 . 신규 서원 담당자 연락처 요청하며 명함 전달함 | V24: 2025-056
B25: =IF(ISERROR(VLOOKUP(J25,'==='!B:E,4,FALSE)),"",VLOOKUP(J25,'==='!B:E,4,FALSE)) -> 1월 3주 | C25: 2026-010 | D25: 수어 | E25: KB국민은행 | F25: KB국민은행 | G25: KB국민은행 AI 수어 상담에 대한 챗봇 연계 구축 | H25: 양승구 | I25: 3 제안중 | J25: 46042 | K25: 프로젝트 담당자 변경에 따른 지속적인 관계 개선 작업 진행 | V25: 2025-084
B26: =IF(ISERROR(VLOOKUP(J26,'==='!B:E,4,FALSE)),"",VLOOKUP(J26,'==='!B:E,4,FALSE)) -> 1월 4주 | C26: 2026-010 | D26: 수어 | E26: KB국민은행 | F26: KB국민은행 | G26: KB국민은행 AI 수어 상담에 대한 챗봇 연계 구축 | H26: 양승구 | I26: 3 제안중 | J26: 46050 | K26: 디지털데스크의 화상 시스템 Upgrade 구축시 당사의 수어 솔루션 추가에 따른 협의 미팅 - PC,모바일, DD에서 수어 서비스 시스템이 구축 될 수 있는 방안 협의, 시스템 구서으, 서비스 방아느 구축 일정, M/M 등에 대한 제안 요청 받음 - 견적서 차주 제공 요청 - 진행일정 : 2~3월 RFP 발송, 4중 프로젝트 시작 예정으로 KB데이타시스템 단독 제안으로 구축 * 양방향의 소통과 수어 운영 데이타의 관리 방안에 대한 구축적인 일정 요청 --> 1.30일 정리하여 메일 전송 | V26: 2025-084
B27: =IF(ISERROR(VLOOKUP(J27,'==='!B:E,4,FALSE)),"",VLOOKUP(J27,'==='!B:E,4,FALSE)) -> 2월 1주 | C27: 2026-010 | D27: 수어 | E27: KB국민은행 | F27: KB국민은행 | G27: KB국민은행 AI 수어 상담에 대한 챗봇 연계 구축 | H27: 양승구 | I27: 3 제안중 | J27: 46056 | K27: 견적서 자료 제출 : 3.5억 (300문장 기준), 현재 KB테이타시스템 및 페르미 견적서 통합하여 진행 예정 - 진행일정 : 2~3월 RFP 발송, 4중 프로젝트 시작 예정으로 KB데이타시스템 단독 제안으로 구축 * 양방향의 소통과 수어 운영 데이타의 관리 방안에 대한 구축적인 일정 요청 --> 1.30일 정리하여 메일 전송 완료 | V27: 2025-084
B28: =IF(ISERROR(VLOOKUP(J28,'==='!B:E,4,FALSE)),"",VLOOKUP(J28,'==='!B:E,4,FALSE)) -> 1월 1주 | C28: 2026-009 | D28: 수어 | E28: 120다산콜재단 | F28: 120다산콜재단 | G28: 120다산콜재단 AI수어 시스템 구축 | H28: 양승구 | I28: 3 제안중 | J28: 46027 | K28: 120다산콜센터와 KL큐브 업무 협약식 진행 - 2026.1.5 11:00 120다산콜재단 이사장실, 이사장님 및 관계자 참여하여 업무협약식 진행 - AI수어시스템의 구축, 서비스 고도화 와 수어 상담에 대한 공동 연구 진행 - 우선 사업 진행 사항 : 행정용어 수어 사전 제작을 최우선으로 진행 : 26년 2월가지 서비스 방안 확정, 3월부터 구축하는 방안으로 추진 - 다산콜센터는 홈페이지 및 챗봇 구축 방안으로 협의 진행(스마트 전산부장 업무 미팅 추진) | V28: -
B29: =IF(ISERROR(VLOOKUP(J29,'==='!B:E,4,FALSE)),"",VLOOKUP(J29,'==='!B:E,4,FALSE)) -> 1월 3주 | C29: 2026-009 | D29: 수어 | E29: 120다산콜재단 | F29: 120다산콜재단 | G29: 120다산콜재단 AI수어 시스템 구축 | H29: 양승구 | I29: 3 제안중 | J29: 46041 | K29: 120다산콜센터의 콜 업무 분석을 위한 인력 파견 - 다산콜재단의 수어 상담의 현황 및 업무 분석 후 개선 방안 수립 - 기간 : 1.20 ~ 30일까지 오민규부장 파견하여 업무 분석 진행 후 Report 작성 제안 예정 - 서울시 행정용어집 구축을 위한 사전 자료 분석 : 제안을 위한 제언서 2차 준비 완료 | V29: -
B30: =IF(ISERROR(VLOOKUP(J30,'==='!B:E,4,FALSE)),"",VLOOKUP(J30,'==='!B:E,4,FALSE)) -> 2월 1주 | C30: 2026-009 | D30: 수어 | E30: 120다산콜재단 | F30: 120다산콜재단 | G30: 120다산콜재단 AI수어 시스템 구축 | H30: 양승구 | I30: 3 제안중 | J30: 46057 | K30: 120다산콜센터의 상담콜의 업무 분석 완료(1.30일, 2월 3일 보고서 작성 완료) - 다산콜재단 수어상담 현황 분석자료 완료(보고서 작성) - 다산콜재단은 행정용어집 구축 방향으로 제안 (용어의 선정 - 행정업무 위주로 선정, 홈페이지와 연계 Page로 구성) - 2월 계약, 3월 개발, 4월 오픈 일정으로 진행 예정, 구축 예산 범위로 업무 개발 진행(비용은 차주 확정) | V30: -
B31: =IF(ISERROR(VLOOKUP(J31,'==='!B:E,4,FALSE)),"",VLOOKUP(J31,'==='!B:E,4,FALSE)) -> 1월 1주 | C31: 2026-011 | D31: 수어 | E31: 건양대학교 | F31: 건양대학교 | G31: 건양대학교 간호대학 AI 수어 시스템 구축 | H31: 양승구 | I31: 3 제안중 | J31: 46028 | K31: 당사의 핸드사인 톡톡에 대한솔루션 셜명 - 당사의 제안 솔루션에 대한 호의적인 반응, 현재 당사만 솔루션 검토 진행 중이며, 당사 핸드사인툭톡에서 설문지의 기능을 추가 요청 (개발 가능함) - AI 수어 플랫폼의 핸드사인 버스의 구독형 서비스로 제안, 수어 영상에 관심을 가지고 있으며, 기존에 간호학과에서 청각 장애인을 위한 연구가 많이 이루어 졌음 - "인공지능 수어 통역 건강코칭을 활요한 청각장애인의 고협압 자기관리 중애 개발 및 효과 평가" 3개년 연구 과재로 진행, 개인 연구 과ㅈ제, 비용은 4억 예산 - 진행일정 : 1월 검토 완료, 2월 확정, 3월 계약, 4월 부터 연구과제 진행 의 일정으로 수행 - 지속적인 영업관리로 진행 | V31: -
B32: =IF(ISERROR(VLOOKUP(J32,'==='!B:E,4,FALSE)),"",VLOOKUP(J32,'==='!B:E,4,FALSE)) -> 1월 1주 | C32: 2026-001 | D32: AICC | E32: 모던텍 | F32: 모던텍 | G32: 모던텍 음성봇(SaaS) 도입 및 고객센터 운영 | H32: 오민규 | I32: 3 제안중 | J32: 46028 | K32: - 담당자 미팅 예정 : 1/8 조원부장 | V32: 2025-104
B33: =IF(ISERROR(VLOOKUP(J33,'==='!B:E,4,FALSE)),"",VLOOKUP(J33,'==='!B:E,4,FALSE)) -> 1월 4주 | C33: 2026-007 | D33: 수어 | E33: 문화체육관광부 국립국어원 | F33: 문화체육관광부 국립국어원 | G33: 국립국어원 2026년 한국수어-한국어 사전 자료 집필 | H33: 임철현 | I33: 8 계약완료 | J33: 46050 | K33: - 선급금(70%, 562,990,910원VAT별도) 나라장터 경유 청구완료 L 차주 초 대금수금 예정 | P33: 46020 | Q33: 46371 | R33: =884700000/1.1 -> 8.0427273e+08 | S33: =884700000/1.1 -> 8.0427273e+08 | U33: 단독 | V33: 2025-090
B34: =IF(ISERROR(VLOOKUP(J34,'==='!B:E,4,FALSE)),"",VLOOKUP(J34,'==='!B:E,4,FALSE)) -> 1월 3주 | C34: 2026-007 | D34: 수어 | E34: 문화체육관광부 국립국어원 | F34: 문화체육관광부 국립국어원 | G34: 국립국어원 2026년 한국수어-한국어 사전 자료 집필 | H34: 임철현 | I34: 8 계약완료 | J34: 46041 | K34: - 선급금(70%) 신청관련 당사 실적증명서 발행 및 장철성부장전달 L 조달청 경유 선급금 신청시 영업팀에서 지원하기로 협의 함 | P34: 46020 | Q34: 46371 | R34: =884700000/1.1 -> 8.0427273e+08 | S34: =884700000/1.1 -> 8.0427273e+08 | U34: 단독 | V34: 2025-090
B35: =IF(ISERROR(VLOOKUP(J35,'==='!B:E,4,FALSE)),"",VLOOKUP(J35,'==='!B:E,4,FALSE)) -> 1월 1주 | C35: 2026-007 | D35: 수어 | E35: 문화체육관광부 국립국어원 | F35: 문화체육관광부 국립국어원 | G35: 국립국어원 2026년 한국수어-한국어 사전 자료 집필 | H35: 임철현 | I35: 8 계약완료 | J35: 46030 | K35: - '26년 착수보고회 진행 일시: 01/09 10:00 | P35: 46020 | Q35: 46371 | R35: =884700000/1.1 -> 8.0427273e+08 | S35: =884700000/1.1 -> 8.0427273e+08 | U35: 단독 | V35: 2025-090
B36: =IF(ISERROR(VLOOKUP(J36,'==='!B:E,4,FALSE)),"",VLOOKUP(J36,'==='!B:E,4,FALSE)) -> 2월 1주 | C36: 2026-008 | D36: 수어 | E36: 서울의료원 | F36: 서울경제진흥원 | G36: 2025년 테스트베드 서울 실증 지원사업(서울의료원) | H36: 임철현 | I36: 8 계약완료 | J36: 46055 | K36: 서울의료원 미팅 - 키오스크(안내형1, 발급기3) 확정, 설치 위치 실사 및 시공관련(통신 3곳 및 전원1곳)시공필요 견적의뢰(C&S에너지) - 시공비용관련 정상욱부장 경유 SBA에 문의 진행시 수행계획에 대한 변경보고 또는 자부담 처리 가능함 - 키오스크 구매비용에 시공비 포함하여 처리하는 방식으로 진행코자 한 | O36: 45924 | P36: 45915 | Q36: 2026-0914 | R36: =200000000/1.1 -> 1.8181818e+08 | S36: =200000000/1.1 -> 1.8181818e+08 | U36: 단독 | V36: 2025-045
B37: =IF(ISERROR(VLOOKUP(J37,'==='!B:E,4,FALSE)),"",VLOOKUP(J37,'==='!B:E,4,FALSE)) -> 1월 4주 | C37: 2026-008 | D37: 수어 | E37: 서울의료원 | F37: 서울경제진흥원 | G37: 2025년 테스트베드 서울 실증 지원사업(서울의료원) | H37: 임철현 | I37: 8 계약완료 | J37: 46048 | K37: 과제관련 키오스크(배리어프리 안내형 1식, 발급기 3식)관련 발주 및 키오스크업체와 납품 협의 - 포씨게이트 '서울의료원 발급시스템' 원 소스 공유 요청 - 차주 서울의료원 미팅시 키오스크 설치위치 및 시공관련 실사 진행예정, 서울의료원 전산팀 일정 확인 중 | O37: 45924 | P37: 45915 | Q37: 2026-0914 | R37: =200000000/1.1 -> 1.8181818e+08 | S37: =200000000/1.1 -> 1.8181818e+08 | U37: 단독 | V37: 2025-045
B38: =IF(ISERROR(VLOOKUP(J38,'==='!B:E,4,FALSE)),"",VLOOKUP(J38,'==='!B:E,4,FALSE)) -> 1월 3주 | C38: 2026-008 | D38: 수어 | E38: 서울의료원 | F38: 서울경제진흥원 | G38: 2025년 테스트베드 서울 실증 지원사업(서울의료원) | H38: 임철현 | I38: 8 계약완료 | J38: 46043 | K38: 과제관련 키오스크(배리어프리 안내형 1식, 발급기 3식)관련 발주서 내용관련 키오스크업체와 협의 - 납품은 2월 중 진행, 무상유지보수 기간은 실증기관 종료 이후인 '26.09.15일부터 2년간 협의 - 대금지급은 납품 후 30일 이내 현금 지급 협의 * 서울의료원 2월 행사관련 안내형키오스크 대여관련 엘토브와 협의 진행(대여기간 확인 후 재협의 예정) | O38: 45924 | P38: 45915 | Q38: 2026-0914 | R38: =200000000/1.1 -> 1.8181818e+08 | S38: =200000000/1.1 -> 1.8181818e+08 | U38: 단독 | V38: 2025-045
B39: =IF(ISERROR(VLOOKUP(J39,'==='!B:E,4,FALSE)),"",VLOOKUP(J39,'==='!B:E,4,FALSE)) -> 1월 1주 | C39: 2026-008 | D39: 수어 | E39: 서울의료원 | F39: 서울경제진흥원 | G39: 2025년 테스트베드 서울 실증 지원사업(서울의료원) | H39: 임철현 | I39: 8 계약완료 | J39: 46029 | K39: 과제관련 키오스크(배리어프리 안내형 1식, 발급기 3식)관련 내부 사전 품의 완료 - 배리어프리 안내형 1식 키오스크 -> 엘토브 43인치 스탠드형 BF인증 키오스크 선정 - 발급기 3식 키오스그 -> 포시케이트 21.5인치 발급기 3식 선정, 발급시스템 연동관련 금액 조정 협의 중 | O39: 45924 | P39: 45915 | Q39: 2026-0914 | R39: =200000000/1.1 -> 1.8181818e+08 | S39: =200000000/1.1 -> 1.8181818e+08 | U39: 단독 | V39: 2025-045
B40: =IF(ISERROR(VLOOKUP(J40,'==='!B:E,4,FALSE)),"",VLOOKUP(J40,'==='!B:E,4,FALSE)) -> 1월 1주 | C40: 2026-008 | D40: 수어 | E40: 서울의료원 | F40: 서울경제진흥원원 | G40: 2025년 테스트베드 서울 실증 지원사업(서울의료원) | H40: 임철현 | I40: 8 계약완료 | J40: 46024 | K40: 과제관련 당사 핸드사인톡톡 조달청'혁신제품' 선정 및 유지보수 금액관련 협의, 의료원 내부 보고관련 사전 협의 및 관련 견적서(비교) 2부 제공 완료 | O40: 45924 | P40: 45915 | Q40: 2026-0914 | R40: =200000000/1.1 -> 1.8181818e+08 | S40: =200000000/1.1 -> 1.8181818e+08 | U40: 단독 | V40: 2025-045
...

Sheet Sheet2

Sheet ===
C2: 월 | D2: 주차
B3: 45992 | C3: =MONTH(B3) -> 12 | D3: =WEEKNUM(B3,15) -> 49
B4: 45993 | C4: =MONTH(B4) -> 12 | D4: =WEEKNUM(B4,15) -> 49
B5: 45994 | C5: =MONTH(B5) -> 12 | D5: =WEEKNUM(B5,15) -> 49 | E5: 12월 1주
B6: 45995 | C6: =MONTH(B6) -> 12 | D6: =WEEKNUM(B6,15) -> 49 | E6: 12월 2주
B7: 45996 | C7: =MONTH(B7) -> 12 | D7: =WEEKNUM(B7,15) -> 50 | E7: 12월 2주
B8: 45997 | C8: =MONTH(B8) -> 12 | D8: =WEEKNUM(B8,15) -> 50 | E8: =E7 -> 12월 2주
B9: 45998 | C9: =MONTH(B9) -> 12 | D9: =WEEKNUM(B9,15) -> 50 | E9: =E8 -> 12월 2주
B10: 45999 | C10: =MONTH(B10) -> 12 | D10: =WEEKNUM(B10,15) -> 50 | E10: =E9 -> 12월 2주
B11: 46000 | C11: =MONTH(B11) -> 12 | D11: =WEEKNUM(B11,15) -> 50 | E11: =E10 -> 12월 2주
B12: 46001 | C12: =MONTH(B12) -> 12 | D12: =WEEKNUM(B12,15) -> 50 | E12: =E11 -> 12월 2주
B13: 46002 | C13: =MONTH(B13) -> 12 | D13: =WEEKNUM(B13,15) -> 50 | E13: =E12 -> 12월 2주
B14: 46003 | C14: =MONTH(B14) -> 12 | D14: =WEEKNUM(B14,15) -> 51 | E14: 12월 3주
B15: 46004 | C15: =MONTH(B15) -> 12 | D15: =WEEKNUM(B15,15) -> 51 | E15: =E14 -> 12월 3주
B16: 46005 | C16: =MONTH(B16) -> 12 | D16: =WEEKNUM(B16,15) -> 51 | E16: =E15 -> 12월 3주
B17: 46006 | C17: =MONTH(B17) -> 12 | D17: =WEEKNUM(B17,15) -> 51 | E17: =E16 -> 12월 3주
B18: 46007 | C18: =MONTH(B18) -> 12 | D18: =WEEKNUM(B18,15) -> 51 | E18: =E17 -> 12월 3주
B19: 46008 | C19: =MONTH(B19) -> 12 | D19: =WEEKNUM(B19,15) -> 51 | E19: =E18 -> 12월 3주
B20: 46009 | C20: =MONTH(B20) -> 12 | D20: =WEEKNUM(B20,15) -> 51 | E20: =E19 -> 12월 3주
B21: 46010 | C21: =MONTH(B21) -> 12 | D21: =WEEKNUM(B21,15) -> 52 | E21: 12월 4주
B22: 46011 | C22: =MONTH(B22) -> 12 | D22: =WEEKNUM(B22,15) -> 52 | E22: =E21 -> 12월 4주
B23: 46012 | C23: =MONTH(B23) -> 12 | D23: =WEEKNUM(B23,15) -> 52 | E23: =E22 -> 12월 4주
B24: 46013 | C24: =MONTH(B24) -> 12 | D24: =WEEKNUM(B24,15) -> 52 | E24: =E23 -> 12월 4주
B25: 46014 | C25: =MONTH(B25) -> 12 | D25: =WEEKNUM(B25,15) -> 52 | E25: =E24 -> 12월 4주
B26: 46015 | C26: =MONTH(B26) -> 12 | D26: =WEEKNUM(B26,15) -> 52 | E26: =E25 -> 12월 4주
B27: 46016 | C27: =MONTH(B27) -> 12 | D27: =WEEKNUM(B27,15) -> 52 | E27: =E26 -> 12월 4주
B28: 46017 | C28: =MONTH(B28) -> 12 | D28: =WEEKNUM(B28,15) -> 53 | E28: 12월 5주
B29: 46018 | C29: =MONTH(B29) -> 12 | D29: =WEEKNUM(B29,15) -> 53 | E29: =E28 -> 12월 5주
B30: 46019 | C30: =MONTH(B30) -> 12 | D30: =WEEKNUM(B30,15) -> 53 | E30: =E29 -> 12월 5주
B31: 46020 | C31: =MONTH(B31) -> 12 | D31: =WEEKNUM(B31,15) -> 53 | E31: =E30 -> 12월 5주
B32: 46021 | C32: =MONTH(B32) -> 12 | D32: =WEEKNUM(B32,15) -> 53 | E32: =E31 -> 12월 5주
B33: 46022 | C33: =MONTH(B33) -> 12 | D33: =WEEKNUM(B33,15) -> 53 | E33: =E32 -> 12월 5주
B34: 46023 | C34: =MONTH(B34) -> 1 | D34: =WEEKNUM(B34,15) -> 1 | E34: =E33 -> 12월 5주
B35: 46024 | C35: =MONTH(B35) -> 1 | D35: =WEEKNUM(B35,15) -> 2 | E35: 1월 1주
B36: 46025 | C36: =MONTH(B36) -> 1 | D36: =WEEKNUM(B36,15) -> 2 | E36: =E35 -> 1월 1주
B37: 46026 | C37: =MONTH(B37) -> 1 | D37: =WEEKNUM(B37,15) -> 2 | E37: =E36 -> 1월 1주
B38: 46027 | C38: =MONTH(B38) -> 1 | D38: =WEEKNUM(B38,15) -> 2 | E38: =E37 -> 1월 1주
B39: 46028 | C39: =MONTH(B39) -> 1 | D39: =WEEKNUM(B39,15) -> 2 | E39: =E38 -> 1월 1주
B40: 46029 | C40: =MONTH(B40) -> 1 | D40: =WEEKNUM(B40,15) -> 2 | E40: =E39 -> 1월 1주
B41: 46030 | C41: =MONTH(B41) -> 1 | D41: =WEEKNUM(B41,15) -> 2 | E41: =E40 -> 1월 1주
...

Sheet 25년 매출운영 현황
B2: ■ 2025년도 영업진행 및 계약 현황
I3: ↓ 이 부분만 수기로 작성하시기 바랍니다. ↓ | S3: ※ 금액: 단위 천원. VAT별도
B4: 파이프라인 ID | C4: 분야 | D4: 고객사 | E4: 발주처 | F4: 사업명 | G4: 담당 | H4: 진행단계 | I4: 계약일자 | J4: 프로젝트 기간 | L4: 계약 | N4: 매출 금액 | R4: 견적 제공 금액 | S4: 비고
J5: 시작 | K5: 종료 | L5: 수주금액 | M5: 계약금액 | N5: 45931 | O5: 45962 | P5: 45992 | Q5: 합계(10월~12월)
B6: ='2025년 주요추진사업(NEW)'!B4 -> 2025-001 | C6: ='2025년 주요추진사업(NEW)'!C4 -> AICC | D6: ='2025년 주요추진사업(NEW)'!D4 -> KB국민은행 | E6: ='2025년 주요추진사업(NEW)'!E4 -> SK쉴더스 | F6: ='2025년 주요추진사업(NEW)'!F4 -> KB국민은행 SynK 활용 AICC 통합관리포탈 구축 | G6: ='2025년 주요추진사업(NEW)'!G4 -> 함영민 | H6: ='2025년 주요추진사업(NEW)'!H4 -> 2 견적제출 | Q6: =SUM(N6:P6) -> 0 | R6: =VLOOKUP(B6, '2025년 주요추진사업(NEW)'!B:O, 14, FALSE) -> 2637000
B7: ='2025년 주요추진사업(NEW)'!B5 -> 2025-002 | C7: ='2025년 주요추진사업(NEW)'!C5 -> AICC | D7: ='2025년 주요추진사업(NEW)'!D5 -> 한국도로교통공단 | E7: ='2025년 주요추진사업(NEW)'!E5 -> 모비젠 | F7: ='2025년 주요추진사업(NEW)'!F5 -> 한국도로교통공단 STT API 개발 | G7: ='2025년 주요추진사업(NEW)'!G5 -> 함영민 | H7: ='2025년 주요추진사업(NEW)'!H5 -> 5 DROP | Q7: =SUM(N7:P7) -> 0 | R7: =VLOOKUP(B7, '2025년 주요추진사업(NEW)'!B:O, 14, FALSE) -> 0
B8: ='2025년 주요추진사업(NEW)'!B6 -> 2025-003 | C8: ='2025년 주요추진사업(NEW)'!C6 -> AICC | D8: ='2025년 주요추진사업(NEW)'!D6 -> 현대캐피탈 | E8: ='2025년 주요추진사업(NEW)'!E6 -> KT | F8: ='2025년 주요추진사업(NEW)'!F6 -> 현대캐피탈 LLM 기반 인바운드 AI음성봇 구축 | G8: ='2025년 주요추진사업(NEW)'!G6 -> 함영민 | H8: ='2025년 주요추진사업(NEW)'!H6 -> 5 DROP | Q8: =SUM(N8:P8) -> 0 | R8: =VLOOKUP(B8, '2025년 주요추진사업(NEW)'!B:O, 14, FALSE) -> 0
B9: ='2025년 주요추진사업(NEW)'!B7 -> 2025-004 | C9: ='2025년 주요추진사업(NEW)'!C7 -> AICC | D9: ='2025년 주요추진사업(NEW)'!D7 -> 평택시청 | E9: ='2025년 주요추진사업(NEW)'!E7 -> KT평택지사 | F9: ='2025년 주요추진사업(NEW)'!F7 -> 평택시청 AI 기반 민원분석시스템 구축 | G9: ='2025년 주요추진사업(NEW)'!G7 -> 함영민 | H9: ='2025년 주요추진사업(NEW)'!H7 -> 1 영업중 | Q9: =SUM(N9:P9) -> 0 | R9: =VLOOKUP(B9, '2025년 주요추진사업(NEW)'!B:O, 14, FALSE) -> 0
B10: ='2025년 주요추진사업(NEW)'!B8 -> 2025-005 | C10: ='2025년 주요추진사업(NEW)'!C8 -> AICC | D10: ='2025년 주요추진사업(NEW)'!D8 -> KT | E10: ='2025년 주요추진사업(NEW)'!E8 -> - | F10: ='2025년 주요추진사업(NEW)'!F8 -> KT EasyCMS(봇프레임웍) 운영유지보수 지명 입찰 | G10: ='2025년 주요추진사업(NEW)'!G8 -> 함영민 | H10: ='2025년 주요추진사업(NEW)'!H8 -> 3 제안중 | Q10: =SUM(N10:P10) -> 0 | R10: =VLOOKUP(B10, '2025년 주요추진사업(NEW)'!B:O, 14, FALSE) -> 0
B11: ='2025년 주요추진사업(NEW)'!B9 -> 2025-006 | C11: ='2025년 주요추진사업(NEW)'!C9 -> AICC | D11: ='2025년 주요추진사업(NEW)'!D9 -> KDB생명 | E11: ='2025년 주요추진사업(NEW)'!E9 -> 코난테크놀로지 | F11: ='2025년 주요추진사업(NEW)'!F9 -> KDB생명 콜센터 실시간 STT 구축 | G11: ='2025년 주요추진사업(NEW)'!G9 -> 함영민 | H11: ='2025년 주요추진사업(NEW)'!H9 -> 2 견적제출 | Q11: =SUM(N11:P11) -> 0 | R11: =VLOOKUP(B11, '2025년 주요추진사업(NEW)'!B:O, 14, FALSE) -> 0
B12: ='2025년 주요추진사업(NEW)'!B10 -> 2025-007 | C12: ='2025년 주요추진사업(NEW)'!C10 -> AICC | D12: ='2025년 주요추진사업(NEW)'!D10 -> 중앙전파관리소 | E12: ='2025년 주요추진사업(NEW)'!E10 -> 코난테크놀로지 | F12: ='2025년 주요추진사업(NEW)'!F10 -> 중앙전파관리소 방송 프로그램 심의 분석 구축 사업(STT 부문 참여) | G12: ='2025년 주요추진사업(NEW)'!G10 -> 함영민 | H12: ='2025년 주요추진사업(NEW)'!H10 -> 3 제안중 | Q12: =SUM(N12:P12) -> 0 | R12: =VLOOKUP(B12, '2025년 주요추진사업(NEW)'!B:O, 14, FALSE) -> 0
